Workbook
Name Group_A1: А1!$J$6:$U$30
Name Group_A2: А2!$J$6:$U$30
Name Group_A3: А3!$J$6:$U$30
Name Group_A4: А4!$J$6:$U$30
Name Group_A5: А5!$J$6:$U$30
Name Group_A6: А6!$J$6:$U$30
Name Group_A7: А7!$J$6:$U$30
Name Group_A8: А8!$J$6:$U$30
Name Group_B1: 'B1'!$J$6:$U$30
Name Group_B2: 'B2'!$J$6:$U$30
Name Group_B3: В3_2!$J$6:$V$33
Name Group_B4: 'B4'!$J$6:$U$30
Name Group_B5: 'B5'!$J$6:$U$30
Name Group_B6: 'B6'!$J$6:$U$30
Name Group_B7: 'B7'!$J$6:$U$30
Name Group_B8: 'B8'!$J$6:$U$30
Name Group_C1: С1!$J$6:$U$30
Name Group_C2: 'C2_2'!$J$6:$V$33
Name Group_C3: 'C3_2'!$J$6:$V$33
Name Group_C4: 'C4_2'!$J$6:$V$33
Name Group_C5: 'C5_2'!$J$6:$V$33
Name Group_C6: 'C6_2'!$J$6:$V$33
Name Group_C7: 'C7_2'!$J$6:$V$33
Name Group_C8: 'C8_2'!$J$6:$V$33
Name Group_D1: D1_2!$J$6:$V$33
Name Group_D2: D2_2!$J$6:$V$33
Name Group_D3: D3_2!$J$6:$V$33
Name Group_D4: D4_2!$J$6:$V$33
Name Group_D5: D5_2!$J$6:$V$33
Name Group_D6: D6_2!$J$6:$V$33
Name Group_D7: D7_2!$J$6:$V$33
Name Group_D8: D8_2!$J$6:$V$33
Name Group_E1: 'E1'!$J$6:$U$30
Name Group_E2: 'E2'!$J$6:$U$30
Name Group_E3: 'E3'!$J$6:$U$30
Name Group_E4: 'E4'!$J$6:$U$30
Name Group_E5: 'E5'!$J$6:$U$30
Name Group_E6: 'E6'!$J$6:$U$30
Name Group_E7: 'E7'!$J$6:$U$30
Name Group_E8: 'E8'!$J$6:$U$30
Name Super: Суперлига!$J$6:$U$30
Name Игрок1: 'B1'!$D$7
Name Игрок1: 'B2'!$D$7
Name Игрок1: 'B3'!$D$7
Name Игрок1: 'B4'!$D$7
Name Игрок1: 'B5'!$D$7
Name Игрок1: 'B6'!$D$7
Name Игрок1: 'B7'!$D$7
Name Игрок1: 'B8'!$D$7
Name Игрок1: 'C2_2'!$D$7
Name Игрок1: 'C3_2'!$D$7
Name Игрок1: 'C4_2'!$D$7
Name Игрок1: 'C5_2'!$D$7
Name Игрок1: 'C6_2'!$D$7
Name Игрок1: 'C7_2'!$D$7
Name Игрок1: 'C8_2'!$D$7
Name Игрок1: 'D1'!$D$7
Name Игрок1: D1_2!$D$7
Name Игрок1: 'D2'!$D$7
Name Игрок1: D2_2!$D$7

Sheet Суперлига
D1: Турнир Открытое первенство города Астана (лиги) | K1: Дата: | L1: 46033
K4: матчи до | M4: 3 | N4: побед
C5: =IF(COUNTIF(D7:D14,"")>0,1,0) -> 0 | E5: =IF((COUNTIF(L33:R60,">""")+COUNTIF(T7:U30,">"""))>0,1,0) -> 1
C6: № | D6: Участники турнира | E6: Рейтинг | G6: № | H6: Разряд | I6: R | J6: Фамилия Имя | K6: 1 | L6: 2 | M6: 3 | N6: 4 | O6: 5 | P6: 6 | Q6: 7 | R6: 8 | S6: Очки | T6: Соотн. | U6: Место
C7: 1 | D7: Гилязов Роман | G7: 1 | H7: КМС | I7: 41 | J7: Гилязов Роман+ | L7: =IF(LEFT(P57,1)="L",0,(IF(P57="","",(IF(LEFT(P57,1)>RIGHT(P57,1),2,1))))) -> 2 | M7: =IF(LEFT(P49,1)="L",0,(IF(P49="","",(IF(LEFT(P49,1)>RIGHT(P49,1),2,1))))) -> 2 | N7: =IF(RIGHT(P53,1)="L",0,(IF(P53="","",(IF(RIGHT(P53,1)>LEFT(P53,1),2,1))))) -> 2 | O7: =IF(LEFT(P41,1)="L",0,(IF(P41="","",(IF(LEFT(P41,1)>RIGHT(P41,1),2,1))))) -> 2 | P7: =IF(RIGHT(P38,1)="L",0,(IF(P38="","",(IF(RIGHT(P38,1)>LEFT(P38,1),2,1))))) -> 2 | Q7: =IF(LEFT(P35,1)="L",0,(IF(P35="","",(IF(LEFT(P35,1)>RIGHT(P35,1),2,1))))) | R7: =IF(RIGHT(P45,1)="L",0,(IF(P45="","",(IF(RIGHT(P45,1)>LEFT(P45,1),2,1))))) -> 2 | S7: =IF((AND(COUNTIF(J7:J30,">""")>2,COUNTIF(P33:P60,">""")>0)),SUM(K7,L7,M7,N7,O7,P7,Q7,R7),"") -> 12 | U7: 1
C8: 2 | D8: Сереке Султан | L8: =IF(LEFT(P57,1)="W",$M$4&":0(W)",IF(LEFT(P57,1)="L","0:"&$M$4&"(L)",IF(P57="","",P57))) -> 3:0 | M8: =IF(LEFT(P49,1)="W",$M$4&":0(W)",IF(LEFT(P49,1)="L","0:"&$M$4&"(L)",IF(P49="","",P49))) -> 3:0 | N8: =IF(RIGHT(P53,1)="W",$M$4&":0(W)",IF(RIGHT(P53,1)="L","0:"&$M$4&"(L)",IF(P53="","",RIGHT(P53,1)&":"&LEFT(P53,1)))) -> 3:0 | O8: =IF(LEFT(P41,1)="W",$M$4&":0(W)",IF(LEFT(P41,1)="L","0:"&$M$4&"(L)",IF(P41="","",P41))) -> 3:2 | P8: =IF(RIGHT(P38,1)="W",$M$4&":0(W)",IF(RIGHT(P38,1)="L","0:"&$M$4&"(L)",IF(P38="","",RIGHT(P38,1)&":"&LEFT(P38,1)))) -> 3:1 | Q8: =IF(LEFT(P35,1)="W",$M$4&":0(W)",IF(LEFT(P35,1)="L","0:"&$M$4&"(L)",IF(P35="","",P35))) | R8: =IF(RIGHT(P45,1)="W",$M$4&":0(W)",IF(RIGHT(P45,1)="L","0:"&$M$4&"(L)",IF(P45="","",RIGHT(P45,1)&":"&LEFT(P45,1)))) -> 3:1
C9: 3 | D9: Болдырев Андрей | L9: =IF(P57="","",IF(Q57="","",Q57)) | M9: =IF(P49="","",IF(Q49="","",Q49)) | N9: =IF(P53="","",IF(Q53="","",REPLACE(SUBSTITUTE(SUBSTITUTE(SUBSTITUTE(SUBSTITUTE(","&Q53,",-","#"),",","-"),"#",","),"-",",-"),1,1,""))) | O9: =IF(P41="","",IF(Q41="","",Q41)) | P9: =IF(P38="","",IF(Q38="","",REPLACE(SUBSTITUTE(SUBSTITUTE(SUBSTITUTE(SUBSTITUTE(","&Q38,",-","#"),",","-"),"#",","),"-",",-"),1,1,""))) | Q9: =IF(P35="","",IF(Q35="","",Q35)) | R9: =IF(P45="","",IF(Q45="","",REPLACE(SUBSTITUTE(SUBSTITUTE(SUBSTITUTE(SUBSTITUTE(","&Q45,",-","#"),",","-"),"#",","),"-",",-"),1,1,"")))
C10: 4 | D10: Кауымбаев Адилет | G10: 2 | H10: КМС | I10: 28 | J10: Сереке Султан+ | K10: =IF(RIGHT(P57,1)="L",0,(IF(P57="","",(IF(RIGHT(P57,1)>LEFT(P57,1),2,1))))) -> 1 | M10: =IF(RIGHT(P54,1)="L",0,(IF(P54="","",(IF(RIGHT(P54,1)>LEFT(P54,1),2,1))))) -> 2 | N10: =IF(LEFT(P50,1)="L",0,(IF(P50="","",(IF(LEFT(P50,1)>RIGHT(P50,1),2,1))))) -> 2 | O10: =IF(RIGHT(P37,1)="L",0,(IF(P37="","",(IF(RIGHT(P37,1)>LEFT(P37,1),2,1))))) -> 1 | P10: =IF(LEFT(P33,1)="L",0,(IF(P33="","",(IF(LEFT(P33,1)>RIGHT(P33,1),2,1))))) -> 2 | Q10: =IF(RIGHT(P47,1)="L",0,(IF(P47="","",(IF(RIGHT(P47,1)>LEFT(P47,1),2,1))))) | R10: =IF(LEFT(P42,1)="L",0,(IF(P42="","",(IF(LEFT(P42,1)>RIGHT(P42,1),2,1))))) -> 2 | S10: =IF((AND(COUNTIF(J7:J30,">""")>2,COUNTIF(P33:P60,">""")>0)),SUM(K10,L10,M10,N10,O10,P10,Q10,R10),"") -> 10 | U10: 2
C11: 5 | D11: Забанов Филипп | K11: =IF(RIGHT(P57,1)="W",$M$4&":0(W)",IF(RIGHT(P57,1)="L","0:"&$M$4&"(L)",IF(P57="","",RIGHT(P57,1)&":"&LEFT(P57,1)))) -> 0:3 | M11: =IF(RIGHT(P54,1)="W",$M$4&":0(W)",IF(RIGHT(P54,1)="L","0:"&$M$4&"(L)",IF(P54="","",RIGHT(P54,1)&":"&LEFT(P54,1)))) -> 3:0 | N11: =IF(LEFT(P50,1)="W",$M$4&":0(W)",IF(LEFT(P50,1)="L","0:"&$M$4&"(L)",IF(P50="","",P50))) -> 3:1 | O11: =IF(RIGHT(P37,1)="W",$M$4&":0(W)",IF(RIGHT(P37,1)="L","0:"&$M$4&"(L)",IF(P37="","",RIGHT(P37,1)&":"&LEFT(P37,1)))) -> 1:3 | P11: =IF(LEFT(P33,1)="W",$M$4&":0(W)",IF(LEFT(P33,1)="L","0:"&$M$4&"(L)",IF(P33="","",P33))) -> 3:2 | Q11: =IF(RIGHT(P47,1)="W",$M$4&":0(W)",IF(RIGHT(P47,1)="L","0:"&$M$4&"(L)",IF(P47="","",RIGHT(P47,1)&":"&LEFT(P47,1)))) | R11: =IF(LEFT(P42,1)="W",$M$4&":0(W)",IF(LEFT(P42,1)="L","0:"&$M$4&"(L)",IF(P42="","",P42))) -> 3:0
C12: 6 | D12: Биятов Ахметбек | K12: =IF(P57="","",IF(Q57="","",REPLACE(SUBSTITUTE(SUBSTITUTE(SUBSTITUTE(SUBSTITUTE(","&Q57,",-","#"),",","-"),"#",","),"-",",-"),1,1,""))) | M12: =IF(P54="","",IF(Q54="","",REPLACE(SUBSTITUTE(SUBSTITUTE(SUBSTITUTE(SUBSTITUTE(","&Q54,",-","#"),",","-"),"#",","),"-",",-"),1,1,""))) | N12: =IF(P50="","",IF(Q50="","",Q50)) | O12: =IF(P37="","",IF(Q37="","",REPLACE(SUBSTITUTE(SUBSTITUTE(SUBSTITUTE(SUBSTITUTE(","&Q37,",-","#"),",","-"),"#",","),"-",",-"),1,1,""))) | P12: =IF(P33="","",IF(Q33="","",Q33)) | Q12: =IF(P47="","",IF(Q47="","",REPLACE(SUBSTITUTE(SUBSTITUTE(SUBSTITUTE(SUBSTITUTE(","&Q47,",-","#"),",","-"),"#",","),"-",",-"),1,1,""))) | R12: =IF(P42="","",IF(Q42="","",Q42))
C13: 7 | D13: Бекназаров Ермек | G13: 3 | I13: 30 | J13: Болдырев Андрей+ | K13: =IF(RIGHT(P49,1)="L",0,(IF(P49="","",(IF(RIGHT(P49,1)>LEFT(P49,1),2,1))))) -> 1 | L13: =IF(LEFT(P54,1)="L",0,(IF(P54="","",(IF(LEFT(P54,1)>RIGHT(P54,1),2,1))))) -> 1 | N13: =IF(LEFT(P58,1)="L",0,(IF(P58="","",(IF(LEFT(P58,1)>RIGHT(P58,1),2,1))))) -> 2 | O13: =IF(LEFT(P34,1)="L",0,(IF(P34="","",(IF(LEFT(P34,1)>RIGHT(P34,1),2,1))))) -> 1 | P13: =IF(RIGHT(P48,1)="L",0,(IF(P48="","",(IF(RIGHT(P48,1)>LEFT(P48,1),2,1))))) -> 1 | Q13: =IF(LEFT(P44,1)="L",0,(IF(P44="","",(IF(LEFT(P44,1)>RIGHT(P44,1),2,1))))) | R13: =IF(RIGHT(P39,1)="L",0,(IF(P39="","",(IF(RIGHT(P39,1)>LEFT(P39,1),2,1))))) -> 2 | S13: =IF((AND(COUNTIF(J7:J30,">""")>2,COUNTIF(P33:P60,">""")>0)),SUM(K13,L13,M13,N13,O13,P13,Q13,R13),"") -> 8 | T13: =5/6 -> 0.83333333 | U13: 7
C14: 8 | D14: Герасименко Геннадий | K14: =IF(RIGHT(P49,1)="W",$M$4&":0(W)",IF(RIGHT(P49,1)="L","0:"&$M$4&"(L)",IF(P49="","",RIGHT(P49,1)&":"&LEFT(P49,1)))) -> 0:3 | L14: =IF(LEFT(P54,1)="W",$M$4&":0(W)",IF(LEFT(P54,1)="L","0:"&$M$4&"(L)",IF(P54="","",P54))) -> 0:3 | N14: =IF(LEFT(P58,1)="W",$M$4&":0(W)",IF(LEFT(P58,1)="L","0:"&$M$4&"(L)",IF(P58="","",P58))) -> 3:0 | O14: =IF(LEFT(P34,1)="W",$M$4&":0(W)",IF(LEFT(P34,1)="L","0:"&$M$4&"(L)",IF(P34="","",P34))) -> 0:3 | P14: =IF(RIGHT(P48,1)="W",$M$4&":0(W)",IF(RIGHT(P48,1)="L","0:"&$M$4&"(L)",IF(P48="","",RIGHT(P48,1)&":"&LEFT(P48,1)))) -> 2:3 | Q14: =IF(LEFT(P44,1)="W",$M$4&":0(W)",IF(LEFT(P44,1)="L","0:"&$M$4&"(L)",IF(P44="","",P44))) | R14: =IF(RIGHT(P39,1)="W",$M$4&":0(W)",IF(RIGHT(P39,1)="L","0:"&$M$4&"(L)",IF(P39="","",RIGHT(P39,1)&":"&LEFT(P39,1)))) -> 3:0
K15: =IF(P49="","",IF(Q49="","",REPLACE(SUBSTITUTE(SUBSTITUTE(SUBSTITUTE(SUBSTITUTE(","&Q49,",-","#"),",","-"),"#",","),"-",",-"),1,1,""))) | L15: =IF(P54="","",IF(Q54="","",Q54)) | N15: =IF(P58="","",IF(Q58="","",Q58)) | O15: =IF(P34="","",IF(Q34="","",Q34)) | P15: =IF(P48="","",IF(Q48="","",REPLACE(SUBSTITUTE(SUBSTITUTE(SUBSTITUTE(SUBSTITUTE(","&Q48,",-","#"),",","-"),"#",","),"-",",-"),1,1,""))) | Q15: =IF(P44="","",IF(Q44="","",Q44)) | R15: =IF(P39="","",IF(Q39="","",REPLACE(SUBSTITUTE(SUBSTITUTE(SUBSTITUTE(SUBSTITUTE(","&Q39,",-","#"),",","-"),"#",","),"-",",-"),1,1,"")))
G16: 4 | H16: КМС | I16: 29 | J16: Кауымбаев Адилет+ | K16: =IF(LEFT(P53,1)="L",0,(IF(P53="","",(IF(LEFT(P53,1)>RIGHT(P53,1),2,1))))) -> 1 | L16: =IF(RIGHT(P50,1)="L",0,(IF(P50="","",(IF(RIGHT(P50,1)>LEFT(P50,1),2,1))))) -> 1 | M16: =IF(RIGHT(P58,1)="L",0,(IF(P58="","",(IF(RIGHT(P58,1)>LEFT(P58,1),2,1))))) -> 1 | O16: =IF(RIGHT(P46,1)="L",0,(IF(P46="","",(IF(RIGHT(P46,1)>LEFT(P46,1),2,1))))) -> 2 | P16: =IF(LEFT(P43,1)="L",0,(IF(P43="","",(IF(LEFT(P43,1)>RIGHT(P43,1),2,1))))) -> 2 | Q16: =IF(RIGHT(P40,1)="L",0,(IF(P40="","",(IF(RIGHT(P40,1)>LEFT(P40,1),2,1))))) | R16: =IF(LEFT(P36,1)="L",0,(IF(P36="","",(IF(LEFT(P36,1)>RIGHT(P36,1),2,1))))) -> 2 | S16: =IF((AND(COUNTIF(J7:J30,">""")>2,COUNTIF(P33:P60,">""")>0)),SUM(K16,L16,M16,N16,O16,P16,Q16,R16),"") -> 9 | U16: 3
K17: =IF(LEFT(P53,1)="W",$M$4&":0(W)",IF(LEFT(P53,1)="L","0:"&$M$4&"(L)",IF(P53="","",P53))) -> 0:3 | L17: =IF(RIGHT(P50,1)="W",$M$4&":0(W)",IF(RIGHT(P50,1)="L","0:"&$M$4&"(L)",IF(P50="","",RIGHT(P50,1)&":"&LEFT(P50,1)))) -> 1:3 | M17: =IF(RIGHT(P58,1)="W",$M$4&":0(W)",IF(RIGHT(P58,1)="L","0:"&$M$4&"(L)",IF(P58="","",RIGHT(P58,1)&":"&LEFT(P58,1)))) -> 0:3 | O17: =IF(RIGHT(P46,1)="W",$M$4&":0(W)",IF(RIGHT(P46,1)="L","0:"&$M$4&"(L)",IF(P46="","",RIGHT(P46,1)&":"&LEFT(P46,1)))) -> 3:2 | P17: =IF(LEFT(P43,1)="W",$M$4&":0(W)",IF(LEFT(P43,1)="L","0:"&$M$4&"(L)",IF(P43="","",P43))) -> 3:1 | Q17: =IF(RIGHT(P40,1)="W",$M$4&":0(W)",IF(RIGHT(P40,1)="L","0:"&$M$4&"(L)",IF(P40="","",RIGHT(P40,1)&":"&LEFT(P40,1)))) | R17: =IF(LEFT(P36,1)="W",$M$4&":0(W)",IF(LEFT(P36,1)="L","0:"&$M$4&"(L)",IF(P36="","",P36))) -> 3:1
K18: =IF(P53="","",IF(Q53="","",Q53)) | L18: =IF(P50="","",IF(Q50="","",REPLACE(SUBSTITUTE(SUBSTITUTE(SUBSTITUTE(SUBSTITUTE(","&Q50,",-","#"),",","-"),"#",","),"-",",-"),1,1,""))) | M18: =IF(P58="","",IF(Q58="","",REPLACE(SUBSTITUTE(SUBSTITUTE(SUBSTITUTE(SUBSTITUTE(","&Q58,",-","#"),",","-"),"#",","),"-",",-"),1,1,""))) | O18: =IF(P46="","",IF(Q46="","",REPLACE(SUBSTITUTE(SUBSTITUTE(SUBSTITUTE(SUBSTITUTE(","&Q46,",-","#"),",","-"),"#",","),"-",",-"),1,1,""))) | P18: =IF(P43="","",IF(Q43="","",Q43)) | Q18: =IF(P40="","",IF(Q40="","",REPLACE(SUBSTITUTE(SUBSTITUTE(SUBSTITUTE(SUBSTITUTE(","&Q40,",-","#"),",","-"),"#",","),"-",",-"),1,1,""))) | R18: =IF(P36="","",IF(Q36="","",Q36))
G19: 5 | H19: КМС | I19: 26 | J19: Забанов Филипп+ | K19: =IF(RIGHT(P41,1)="L",0,(IF(P41="","",(IF(RIGHT(P41,1)>LEFT(P41,1),2,1))))) -> 1 | L19: =IF(LEFT(P37,1)="L",0,(IF(P37="","",(IF(LEFT(P37,1)>RIGHT(P37,1),2,1))))) -> 2 | M19: =IF(RIGHT(P34,1)="L",0,(IF(P34="","",(IF(RIGHT(P34,1)>LEFT(P34,1),2,1))))) -> 2 | N19: =IF(LEFT(P46,1)="L",0,(IF(P46="","",(IF(LEFT(P46,1)>RIGHT(P46,1),2,1))))) -> 1 | P19: =IF(LEFT(P59,1)="L",0,(IF(P59="","",(IF(LEFT(P59,1)>RIGHT(P59,1),2,1))))) -> 1 | Q19: =IF(LEFT(P51,1)="L",0,(IF(P51="","",(IF(LEFT(P51,1)>RIGHT(P51,1),2,1))))) | R19: =IF(RIGHT(P56,1)="L",0,(IF(P56="","",(IF(RIGHT(P56,1)>LEFT(P56,1),2,1))))) -> 1 | S19: =IF((AND(COUNTIF(J7:J30,">""")>2,COUNTIF(P33:P60,">""")>0)),SUM(K19,L19,M19,N19,O19,P19,Q19,R19),"") -> 8 | T19: =6/6 -> 1 | U19: 6
K20: =IF(RIGHT(P41,1)="W",$M$4&":0(W)",IF(RIGHT(P41,1)="L","0:"&$M$4&"(L)",IF(P41="","",RIGHT(P41,1)&":"&LEFT(P41,1)))) -> 2:3 | L20: =IF(LEFT(P37,1)="W",$M$4&":0(W)",IF(LEFT(P37,1)="L","0:"&$M$4&"(L)",IF(P37="","",P37))) -> 3:1 | M20: =IF(RIGHT(P34,1)="W",$M$4&":0(W)",IF(RIGHT(P34,1)="L","0:"&$M$4&"(L)",IF(P34="","",RIGHT(P34,1)&":"&LEFT(P34,1)))) -> 3:0 | N20: =IF(LEFT(P46,1)="W",$M$4&":0(W)",IF(LEFT(P46,1)="L","0:"&$M$4&"(L)",IF(P46="","",P46))) -> 2:3 | P20: =IF(LEFT(P59,1)="W",$M$4&":0(W)",IF(LEFT(P59,1)="L","0:"&$M$4&"(L)",IF(P59="","",P59))) -> 2:3 | Q20: =IF(LEFT(P51,1)="W",$M$4&":0(W)",IF(LEFT(P51,1)="L","0:"&$M$4&"(L)",IF(P51="","",P51))) | R20: =IF(RIGHT(P56,1)="W",$M$4&":0(W)",IF(RIGHT(P56,1)="L","0:"&$M$4&"(L)",IF(P56="","",RIGHT(P56,1)&":"&LEFT(P56,1)))) -> 1:3
K21: =IF(P41="","",IF(Q41="","",REPLACE(SUBSTITUTE(SUBSTITUTE(SUBSTITUTE(SUBSTITUTE(","&Q41,",-","#"),",","-"),"#",","),"-",",-"),1,1,""))) | L21: =IF(P37="","",IF(Q37="","",Q37)) | M21: =IF(P34="","",IF(Q34="","",REPLACE(SUBSTITUTE(SUBSTITUTE(SUBSTITUTE(SUBSTITUTE(","&Q34,",-","#"),",","-"),"#",","),"-",",-"),1,1,""))) | N21: =IF(P46="","",IF(Q46="","",Q46)) | P21: =IF(P59="","",IF(Q59="","",Q59)) | Q21: =IF(P51="","",IF(Q51="","",Q51)) | R21: =IF(P56="","",IF(Q56="","",REPLACE(SUBSTITUTE(SUBSTITUTE(SUBSTITUTE(SUBSTITUTE(","&Q56,",-","#"),",","-"),"#",","),"-",",-"),1,1,"")))
B22: 3:0 | G22: 6 | H22: КМС | I22: 27 | J22: Биятов Ахметбек+ | K22: =IF(LEFT(P38,1)="L",0,(IF(P38="","",(IF(LEFT(P38,1)>RIGHT(P38,1),2,1))))) -> 1 | L22: =IF(RIGHT(P33,1)="L",0,(IF(P33="","",(IF(RIGHT(P33,1)>LEFT(P33,1),2,1))))) -> 1 | M22: =IF(LEFT(P48,1)="L",0,(IF(P48="","",(IF(LEFT(P48,1)>RIGHT(P48,1),2,1))))) -> 2 | N22: =IF(RIGHT(P43,1)="L",0,(IF(P43="","",(IF(RIGHT(P43,1)>LEFT(P43,1),2,1))))) -> 1 | O22: =IF(RIGHT(P59,1)="L",0,(IF(P59="","",(IF(RIGHT(P59,1)>LEFT(P59,1),2,1))))) -> 2 | Q22: =IF(RIGHT(P55,1)="L",0,(IF(P55="","",(IF(RIGHT(P55,1)>LEFT(P55,1),2,1))))) | R22: =IF(LEFT(P52,1)="L",0,(IF(P52="","",(IF(LEFT(P52,1)>RIGHT(P52,1),2,1))))) -> 1 | S22: =IF((AND(COUNTIF(J7:J30,">""")>2,COUNTIF(P33:P60,">""")>0)),SUM(K22,L22,M22,N22,O22,P22,Q22,R22),"") -> 8 | T22: =8/7 -> 1.1428571 | U22: 4
B23: 3:1 | K23: =IF(LEFT(P38,1)="W",$M$4&":0(W)",IF(LEFT(P38,1)="L","0:"&$M$4&"(L)",IF(P38="","",P38))) -> 1:3 | L23: =IF(RIGHT(P33,1)="W",$M$4&":0(W)",IF(RIGHT(P33,1)="L","0:"&$M$4&"(L)",IF(P33="","",RIGHT(P33,1)&":"&LEFT(P33,1)))) -> 2:3 | M23: =IF(LEFT(P48,1)="W",$M$4&":0(W)",IF(LEFT(P48,1)="L","0:"&$M$4&"(L)",IF(P48="","",P48))) -> 3:2 | N23: =IF(RIGHT(P43,1)="W",$M$4&":0(W)",IF(RIGHT(P43,1)="L","0:"&$M$4&"(L)",IF(P43="","",RIGHT(P43,1)&":"&LEFT(P43,1)))) -> 1:3 | O23: =IF(RIGHT(P59,1)="W",$M$4&":0(W)",IF(RIGHT(P59,1)="L","0:"&$M$4&"(L)",IF(P59="","",RIGHT(P59,1)&":"&LEFT(P59,1)))) -> 3:2 | Q23: =IF(RIGHT(P55,1)="W",$M$4&":0(W)",IF(RIGHT(P55,1)="L","0:"&$M$4&"(L)",IF(P55="","",RIGHT(P55,1)&":"&LEFT(P55,1)))) | R23: =IF(LEFT(P52,1)="W",$M$4&":0(W)",IF(LEFT(P52,1)="L","0:"&$M$4&"(L)",IF(P52="","",P52))) -> 2:3
B24: 3:2 | K24: =IF(P38="","",IF(Q38="","",Q38)) | L24: =IF(P33="","",IF(Q33="","",REPLACE(SUBSTITUTE(SUBSTITUTE(SUBSTITUTE(SUBSTITUTE(","&Q33,",-","#"),",","-"),"#",","),"-",",-"),1,1,""))) | M24: =IF(P48="","",IF(Q48="","",Q48)) | N24: =IF(P43="","",IF(Q43="","",REPLACE(SUBSTITUTE(SUBSTITUTE(SUBSTITUTE(SUBSTITUTE(","&Q43,",-","#"),",","-"),"#",","),"-",",-"),1,1,""))) | O24: =IF(P59="","",IF(Q59="","",REPLACE(SUBSTITUTE(SUBSTITUTE(SUBSTITUTE(SUBSTITUTE(","&Q59,",-","#"),",","-"),"#",","),"-",",-"),1,1,""))) | Q24: =IF(P55="","",IF(Q55="","",REPLACE(SUBSTITUTE(SUBSTITUTE(SUBSTITUTE(SUBSTITUTE(","&Q55,",-","#"),",","-"),"#",","),"-",",-"),1,1,""))) | R24: =IF(P52="","",IF(Q52="","",Q52))
B25: 0:3 | G25: 7 | H25: МС | I25: 43 | J25: Бекназаров Ермек | K25: =IF(RIGHT(P35,1)="L",0,(IF(P35="","",(IF(RIGHT(P35,1)>LEFT(P35,1),2,1))))) | L25: =IF(LEFT(P47,1)="L",0,(IF(P47="","",(IF(LEFT(P47,1)>RIGHT(P47,1),2,1))))) | M25: =IF(RIGHT(P44,1)="L",0,(IF(P44="","",(IF(RIGHT(P44,1)>LEFT(P44,1),2,1))))) | N25: =IF(LEFT(P40,1)="L",0,(IF(P40="","",(IF(LEFT(P40,1)>RIGHT(P40,1),2,1))))) | O25: =IF(RIGHT(P51,1)="L",0,(IF(P51="","",(IF(RIGHT(P51,1)>LEFT(P51,1),2,1))))) | P25: =IF(LEFT(P55,1)="L",0,(IF(P55="","",(IF(LEFT(P55,1)>RIGHT(P55,1),2,1))))) | R25: =IF(LEFT(P60,1)="L",0,(IF(P60="","",(IF(LEFT(P60,1)>RIGHT(P60,1),2,1))))) | S25: =IF((AND(COUNTIF(J7:J30,">""")>2,COUNTIF(P33:P60,">""")>0)),SUM(K25,L25,M25,N25,O25,P25,Q25,R25),"") -> 0 | U25: 8
B26: 1:3 | K26: =IF(RIGHT(P35,1)="W",$M$4&":0(W)",IF(RIGHT(P35,1)="L","0:"&$M$4&"(L)",IF(P35="","",RIGHT(P35,1)&":"&LEFT(P35,1)))) | L26: =IF(LEFT(P47)="W",$M$4&":0(W)",IF(LEFT(P47,1)="L","0:"&$M$4&"(L)",IF(P47="","",P47))) | M26: =IF(RIGHT(P44,1)="W",$M$4&":0(W)",IF(RIGHT(P44,1)="L","0:"&$M$4&"(L)",IF(P44="","",RIGHT(P44,1)&":"&LEFT(P44,1)))) | N26: =IF(LEFT(P40,1)="W",$M$4&":0(W)",IF(LEFT(P40,1)="L","0:"&$M$4&"(L)",IF(P40="","",P40))) | O26: =IF(RIGHT(P51,1)="W",$M$4&":0(W)",IF(RIGHT(P51,1)="L","0:"&$M$4&"(L)",IF(P51="","",RIGHT(P51,1)&":"&LEFT(P51,1)))) | P26: =IF(LEFT(P55,1)="W",$M$4&":0(W)",IF(LEFT(P55,1)="L","0:"&$M$4&"(L)",IF(P55="","",P55))) | R26: =IF(LEFT(P60,1)="W",$M$4&":0(W)",IF(LEFT(P60,1)="L","0:"&$M$4&"(L)",IF(P60="","",P60)))
B27: 2:3 | K27: =IF(P35="","",IF(Q35="","",REPLACE(SUBSTITUTE(SUBSTITUTE(SUBSTITUTE(SUBSTITUTE(","&Q35,",-","#"),",","-"),"#",","),"-",",-"),1,1,""))) | L27: =IF(P47="","",IF(Q47="","",Q47)) | M27: =IF(P44="","",IF(Q44="","",REPLACE(SUBSTITUTE(SUBSTITUTE(SUBSTITUTE(SUBSTITUTE(","&Q44,",-","#"),",","-"),"#",","),"-",",-"),1,1,""))) | N27: =IF(P40="","",IF(Q40="","",Q40)) | O27: =IF(P51="","",IF(Q51="","",REPLACE(SUBSTITUTE(SUBSTITUTE(SUBSTITUTE(SUBSTITUTE(","&Q51,",-","#"),",","-"),"#",","),"-",",-"),1,1,""))) | P27: =IF(P55="","",IF(Q55="","",Q55)) | R27: =IF(P60="","",IF(Q60="","",Q60))
B28: W:L | G28: 8 | H28: МС | I28: 36 | J28: Герасименко Геннадий+ | K28: =IF(LEFT(P45,1)="L",0,(IF(P45="","",(IF(LEFT(P45,1)>RIGHT(P45,1),2,1))))) -> 1 | L28: =IF(RIGHT(P42,1)="L",0,(IF(P42="","",(IF(RIGHT(P42,1)>LEFT(P42,1),2,1))))) -> 1 | M28: =IF(LEFT(P39,1)="L",0,(IF(P39="","",(IF(LEFT(P39,1)>RIGHT(P39,1),2,1))))) -> 1 | N28: =IF(RIGHT(P36,1)="L",0,(IF(P36="","",(IF(RIGHT(P36,1)>LEFT(P36,1),2,1))))) -> 1 | O28: =IF(LEFT(P56,1)="L",0,(IF(P56="","",(IF(LEFT(P56,1)>RIGHT(P56,1),2,1))))) -> 2 | P28: =IF(RIGHT(P52,1)="L",0,(IF(P52="","",(IF(RIGHT(P52,1)>LEFT(P52,1),2,1))))) -> 2 | Q28: =IF(RIGHT(P60,1)="L",0,(IF(P60="","",(IF(RIGHT(P60,1)>LEFT(P60,1),2,1))))) | S28: =IF((AND(COUNTIF(J7:J30,">""")>2,COUNTIF(P33:P60,">""")>0)),SUM(K28,L28,M28,N28,O28,P28,Q28,R28),"") -> 8 | T28: =6/6 -> 1 | U28: 5
B29: L:W | K29: =IF(LEFT(P45,1)="W",$M$4&":0(W)",IF(LEFT(P45,1)="L","0:"&$M$4&"(L)",IF(P45="","",P45))) -> 1:3 | L29: =IF(RIGHT(P42,1)="W",$M$4&":0(W)",IF(RIGHT(P42,1)="L","0:"&$M$4&"(L)",IF(P42="","",RIGHT(P42,1)&":"&LEFT(P42,1)))) -> 0:3 | M29: =IF(LEFT(P39,1)="W",$M$4&":0(W)",IF(LEFT(P39,1)="L","0:"&$M$4&"(L)",IF(P39="","",P39))) -> 0:3 | N29: =IF(RIGHT(P36,1)="W",$M$4&":0(W)",IF(RIGHT(P36,1)="L","0:"&$M$4&"(L)",IF(P36="","",RIGHT(P36,1)&":"&LEFT(P36,1)))) -> 1:3 | O29: =IF(LEFT(P56,1)="W",$M$4&":0(W)",IF(LEFT(P56,1)="L","0:"&$M$4&"(L)",IF(P56="","",P56))) -> 3:1 | P29: =IF(RIGHT(P52,1)="W",$M$4&":0(W)",IF(RIGHT(P52,1)="L","0:"&$M$4&"(L)",IF(P52="","",RIGHT(P52,1)&":"&LEFT(P52,1)))) -> 3:2 | Q29: =IF(RIGHT(P60,1)="W",$M$4&":0(W)",IF(RIGHT(P60,1)="L","0:"&$M$4&"(L)",IF(P60="","",RIGHT(P60,1)&":"&LEFT(P60,1))))
B30: 2:0 | K30: =IF(P45="","",IF(Q45="","",Q45)) | L30: =IF(P42="","",IF(Q42="","",REPLACE(SUBSTITUTE(SUBSTITUTE(SUBSTITUTE(SUBSTITUTE(","&Q42,",-","#"),",","-"),"#",","),"-",",-"),1,1,""))) | M30: =IF(P39="","",IF(Q39="","",Q39)) | N30: =IF(P36="","",IF(Q36="","",REPLACE(SUBSTITUTE(SUBSTITUTE(SUBSTITUTE(SUBSTITUTE(","&Q36,",-","#"),",","-"),"#",","),"-",",-"),1,1,""))) | O30: =IF(P56="","",IF(Q56="","",Q56)) | P30: =IF(P52="","",IF(Q52="","",REPLACE(SUBSTITUTE(SUBSTITUTE(SUBSTITUTE(SUBSTITUTE(","&Q52,",-","#"),",","-"),"#",","),"-",",-"),1,1,""))) | Q30: =IF(P60="","",IF(Q60="","",REPLACE(SUBSTITUTE(SUBSTITUTE(SUBSTITUTE(SUBSTITUTE(","&Q60,",-","#"),",","-"),"#",","),"-",",-"),1,1,"")))
B31: 2:1
B32: 1:2 | I32: ю | P32: счет по сетам | Q32: мячи
B33: 0:2 | G33: 1 круг | I33: 10 | J33: =IF(Суперлига!Уч2="","",Суперлига!Уч2) -> Сереке Султан+ | K33: ="-" -> - | L33: =IF(Суперлига!Уч6="","",Суперлига!Уч6) -> Биятов Ахметбек+ | P33: 3:2 | S33: =IF(AND(I33<>"",P33=""),"встреча играется",IF(P33<>"","сыграна","")) -> сыграна
B34: 4:0 | I34: 11 | J34: =IF(Суперлига!Уч3="","",Суперлига!Уч3) -> Болдырев Андрей+ | K34: ="-" -> - | L34: =IF(Суперлига!Уч5="","",Суперлига!Уч5) -> Забанов Филипп+ | P34: 0:3 | S34: =IF(AND(I34<>"",P34=""),"встреча играется",IF(P34<>"","сыграна","")) -> сыграна
B35: 4:1 | J35: =IF(Суперлига!Уч1="","",Суперлига!Уч1) -> Гилязов Роман+ | K35: ="-" -> - | L35: =IF(Суперлига!Уч7="","",Суперлига!Уч7) -> Бекназаров Ермек | S35: =IF(AND(I35<>"",P35=""),"встреча играется",IF(P35<>"","сыграна",""))
B36: 4:2 | I36: 12 | J36: =IF(Суперлига!Уч4="","",Суперлига!Уч4) -> Кауымбаев Адилет+ | K36: ="-" -> - | L36: =IF(Суперлига!Уч8="","",Суперлига!Уч8) -> Герасименко Геннадий+ | P36: 3:1 | S36: =IF(AND(I36<>"",P36=""),"встреча играется",IF(P36<>"","сыграна","")) -> сыграна
B37: 4:3 | G37: 2 круг | I37: 13 | J37: =IF(Суперлига!Уч5="","",Суперлига!Уч5) -> Забанов Филипп+ | K37: ="-" -> - | L37: =IF(Суперлига!Уч2="","",Суперлига!Уч2) -> Сереке Султан+ | P37: 3:1 | S37: =IF(AND(I37<>"",P37=""),"встреча играется",IF(P37<>"","сыграна","")) -> сыграна
B38: 0:4 | I38: 10 | J38: =IF(Суперлига!Уч6="","",Суперлига!Уч6) -> Биятов Ахметбек+ | K38: ="-" -> - | L38: =IF(Суперлига!Уч1="","",Суперлига!Уч1) -> Гилязов Роман+ | P38: 1:3 | S38: =IF(AND(I38<>"",P38=""),"встреча играется",IF(P38<>"","сыграна","")) -> сыграна
B39: 1:4 | I39: 12 | J39: =IF(Суперлига!Уч8="","",Суперлига!Уч8) -> Герасименко Геннадий+ | K39: ="-" -> - | L39: =IF(Суперлига!Уч3="","",Суперлига!Уч3) -> Болдырев Андрей+ | P39: 0:3 | S39: =IF(AND(I39<>"",P39=""),"встреча играется",IF(P39<>"","сыграна","")) -> сыграна
B40: 2:4 | J40: =IF(Суперлига!Уч7="","",Суперлига!Уч7) -> Бекназаров Ермек | K40: ="-" -> - | L40: =IF(Суперлига!Уч4="","",Суперлига!Уч4) -> Кауымбаев Адилет+ | S40: =IF(AND(I40<>"",P40=""),"встреча играется",IF(P40<>"","сыграна",""))
B41: 3:4 | G41: 3 круг | I41: 11 | J41: =IF(Суперлига!Уч1="","",Суперлига!Уч1) -> Гилязов Роман+ | K41: ="-" -> - | L41: =IF(Суперлига!Уч5="","",Суперлига!Уч5) -> Забанов Филипп+ | P41: 3:2 | S41: =IF(AND(I41<>"",P41=""),"встреча играется",IF(P41<>"","сыграна","")) -> сыграна
I42: 9 | J42: =IF(Суперлига!Уч2="","",Суперлига!Уч2) -> Сереке Султан+ | K42: ="-" -> - | L42: =IF(Суперлига!Уч8="","",Суперлига!Уч8) -> Герасименко Геннадий+ | P42: 3:0 | S42: =IF(AND(I42<>"",P42=""),"встреча играется",IF(P42<>"","сыграна","")) -> сыграна
...

Sheet А1
D1: Турнир Открытое первенство города Астана (лиги) | K1: Дата: | L1: =Суперлига!L1 -> 46033
K4: матчи до | M4: 3 | N4: побед
C5: =IF(COUNTIF(D7:D14,"")>0,1,0) -> 0 | E5: =IF((COUNTIF(L33:R60,">""")+COUNTIF(T7:U30,">"""))>0,1,0) -> 1
C6: № | D6: Участники турнира | E6: Рейтинг | G6: № | H6: Разряд | I6: R | J6: Фамилия Имя | K6: 1 | L6: 2 | M6: 3 | N6: 4 | O6: 5 | P6: 6 | Q6: 7 | R6: 8 | S6: Очки | T6: Соотн. | U6: Место
C7: 1 | D7: Дуйсенбай Есенали | G7: 1 | H7: КМС | I7: 27 | J7: Дуйсенбай Есенали | L7: =IF(LEFT(P57,1)="L",0,(IF(P57="","",(IF(LEFT(P57,1)>RIGHT(P57,1),2,1))))) | M7: =IF(LEFT(P49,1)="L",0,(IF(P49="","",(IF(LEFT(P49,1)>RIGHT(P49,1),2,1))))) | N7: =IF(RIGHT(P53,1)="L",0,(IF(P53="","",(IF(RIGHT(P53,1)>LEFT(P53,1),2,1))))) | O7: =IF(LEFT(P41,1)="L",0,(IF(P41="","",(IF(LEFT(P41,1)>RIGHT(P41,1),2,1))))) | P7: =IF(RIGHT(P38,1)="L",0,(IF(P38="","",(IF(RIGHT(P38,1)>LEFT(P38,1),2,1))))) | Q7: =IF(LEFT(P35,1)="L",0,(IF(P35="","",(IF(LEFT(P35,1)>RIGHT(P35,1),2,1))))) | R7: =IF(RIGHT(P45,1)="L",0,(IF(P45="","",(IF(RIGHT(P45,1)>LEFT(P45,1),2,1))))) | S7: =IF((AND(COUNTIF(J7:J30,">""")>2,COUNTIF(P33:P60,">""")>0)),SUM(K7,L7,M7,N7,O7,P7,Q7,R7),"") -> 0 | U7: 8
C8: 2 | D8: Токтамыс Нурбол | L8: =IF(LEFT(P57,1)="W",$M$4&":0(W)",IF(LEFT(P57,1)="L","0:"&$M$4&"(L)",IF(P57="","",P57))) | M8: =IF(LEFT(P49,1)="W",$M$4&":0(W)",IF(LEFT(P49,1)="L","0:"&$M$4&"(L)",IF(P49="","",P49))) | N8: =IF(RIGHT(P53,1)="W",$M$4&":0(W)",IF(RIGHT(P53,1)="L","0:"&$M$4&"(L)",IF(P53="","",RIGHT(P53,1)&":"&LEFT(P53,1)))) | O8: =IF(LEFT(P41,1)="W",$M$4&":0(W)",IF(LEFT(P41,1)="L","0:"&$M$4&"(L)",IF(P41="","",P41))) | P8: =IF(RIGHT(P38,1)="W",$M$4&":0(W)",IF(RIGHT(P38,1)="L","0:"&$M$4&"(L)",IF(P38="","",RIGHT(P38,1)&":"&LEFT(P38,1)))) | Q8: =IF(LEFT(P35,1)="W",$M$4&":0(W)",IF(LEFT(P35,1)="L","0:"&$M$4&"(L)",IF(P35="","",P35))) | R8: =IF(RIGHT(P45,1)="W",$M$4&":0(W)",IF(RIGHT(P45,1)="L","0:"&$M$4&"(L)",IF(P45="","",RIGHT(P45,1)&":"&LEFT(P45,1))))
C9: 3 | D9: Ибраев Ерлан | L9: =IF(P57="","",IF(Q57="","",Q57)) | M9: =IF(P49="","",IF(Q49="","",Q49)) | N9: =IF(P53="","",IF(Q53="","",REPLACE(SUBSTITUTE(SUBSTITUTE(SUBSTITUTE(SUBSTITUTE(","&Q53,",-","#"),",","-"),"#",","),"-",",-"),1,1,""))) | O9: =IF(P41="","",IF(Q41="","",Q41)) | P9: =IF(P38="","",IF(Q38="","",REPLACE(SUBSTITUTE(SUBSTITUTE(SUBSTITUTE(SUBSTITUTE(","&Q38,",-","#"),",","-"),"#",","),"-",",-"),1,1,""))) | Q9: =IF(P35="","",IF(Q35="","",Q35)) | R9: =IF(P45="","",IF(Q45="","",REPLACE(SUBSTITUTE(SUBSTITUTE(SUBSTITUTE(SUBSTITUTE(","&Q45,",-","#"),",","-"),"#",","),"-",",-"),1,1,"")))
C10: 4 | D10: Тажиев Нурсултан | G10: 2 | H10: КМС | I10: 34 | J10: Токтамыс Нурбол+ | K10: =IF(RIGHT(P57,1)="L",0,(IF(P57="","",(IF(RIGHT(P57,1)>LEFT(P57,1),2,1))))) | M10: =IF(RIGHT(P54,1)="L",0,(IF(P54="","",(IF(RIGHT(P54,1)>LEFT(P54,1),2,1))))) -> 2 | N10: =IF(LEFT(P50,1)="L",0,(IF(P50="","",(IF(LEFT(P50,1)>RIGHT(P50,1),2,1))))) -> 2 | O10: =IF(RIGHT(P37,1)="L",0,(IF(P37="","",(IF(RIGHT(P37,1)>LEFT(P37,1),2,1))))) -> 1 | P10: =IF(LEFT(P33,1)="L",0,(IF(P33="","",(IF(LEFT(P33,1)>RIGHT(P33,1),2,1))))) -> 2 | Q10: =IF(RIGHT(P47,1)="L",0,(IF(P47="","",(IF(RIGHT(P47,1)>LEFT(P47,1),2,1))))) -> 2 | R10: =IF(LEFT(P42,1)="L",0,(IF(P42="","",(IF(LEFT(P42,1)>RIGHT(P42,1),2,1))))) -> 1 | S10: =IF((AND(COUNTIF(J7:J30,">""")>2,COUNTIF(P33:P60,">""")>0)),SUM(K10,L10,M10,N10,O10,P10,Q10,R10),"") -> 10 | U10: 3
C11: 5 | D11: Суртубаев Марат | K11: =IF(RIGHT(P57,1)="W",$M$4&":0(W)",IF(RIGHT(P57,1)="L","0:"&$M$4&"(L)",IF(P57="","",RIGHT(P57,1)&":"&LEFT(P57,1)))) | M11: =IF(RIGHT(P54,1)="W",$M$4&":0(W)",IF(RIGHT(P54,1)="L","0:"&$M$4&"(L)",IF(P54="","",RIGHT(P54,1)&":"&LEFT(P54,1)))) -> 3:1 | N11: =IF(LEFT(P50,1)="W",$M$4&":0(W)",IF(LEFT(P50,1)="L","0:"&$M$4&"(L)",IF(P50="","",P50))) -> 3:1 | O11: =IF(RIGHT(P37,1)="W",$M$4&":0(W)",IF(RIGHT(P37,1)="L","0:"&$M$4&"(L)",IF(P37="","",RIGHT(P37,1)&":"&LEFT(P37,1)))) -> 2:3 | P11: =IF(LEFT(P33,1)="W",$M$4&":0(W)",IF(LEFT(P33,1)="L","0:"&$M$4&"(L)",IF(P33="","",P33))) -> 3:1 | Q11: =IF(RIGHT(P47,1)="W",$M$4&":0(W)",IF(RIGHT(P47,1)="L","0:"&$M$4&"(L)",IF(P47="","",RIGHT(P47,1)&":"&LEFT(P47,1)))) -> 3:0 | R11: =IF(LEFT(P42,1)="W",$M$4&":0(W)",IF(LEFT(P42,1)="L","0:"&$M$4&"(L)",IF(P42="","",P42))) -> 1:3
C12: 6 | D12: Нурмухамет Данияр | K12: =IF(P57="","",IF(Q57="","",REPLACE(SUBSTITUTE(SUBSTITUTE(SUBSTITUTE(SUBSTITUTE(","&Q57,",-","#"),",","-"),"#",","),"-",",-"),1,1,""))) | M12: =IF(P54="","",IF(Q54="","",REPLACE(SUBSTITUTE(SUBSTITUTE(SUBSTITUTE(SUBSTITUTE(","&Q54,",-","#"),",","-"),"#",","),"-",",-"),1,1,""))) | N12: =IF(P50="","",IF(Q50="","",Q50)) | O12: =IF(P37="","",IF(Q37="","",REPLACE(SUBSTITUTE(SUBSTITUTE(SUBSTITUTE(SUBSTITUTE(","&Q37,",-","#"),",","-"),"#",","),"-",",-"),1,1,""))) | P12: =IF(P33="","",IF(Q33="","",Q33)) | Q12: =IF(P47="","",IF(Q47="","",REPLACE(SUBSTITUTE(SUBSTITUTE(SUBSTITUTE(SUBSTITUTE(","&Q47,",-","#"),",","-"),"#",","),"-",",-"),1,1,""))) | R12: =IF(P42="","",IF(Q42="","",Q42))
C13: 7 | D13: Утельбеков Ермек | G13: 3 | H13: КМС | I13: 28 | J13: Ибраев Ерлан+ | K13: =IF(RIGHT(P49,1)="L",0,(IF(P49="","",(IF(RIGHT(P49,1)>LEFT(P49,1),2,1))))) | L13: =IF(LEFT(P54,1)="L",0,(IF(P54="","",(IF(LEFT(P54,1)>RIGHT(P54,1),2,1))))) -> 1 | N13: =IF(LEFT(P58,1)="L",0,(IF(P58="","",(IF(LEFT(P58,1)>RIGHT(P58,1),2,1))))) -> 1 | O13: =IF(LEFT(P34,1)="L",0,(IF(P34="","",(IF(LEFT(P34,1)>RIGHT(P34,1),2,1))))) -> 1 | P13: =IF(RIGHT(P48,1)="L",0,(IF(P48="","",(IF(RIGHT(P48,1)>LEFT(P48,1),2,1))))) -> 1 | Q13: =IF(LEFT(P44,1)="L",0,(IF(P44="","",(IF(LEFT(P44,1)>RIGHT(P44,1),2,1))))) -> 2 | R13: =IF(RIGHT(P39,1)="L",0,(IF(P39="","",(IF(RIGHT(P39,1)>LEFT(P39,1),2,1))))) -> 2 | S13: =IF((AND(COUNTIF(J7:J30,">""")>2,COUNTIF(P33:P60,">""")>0)),SUM(K13,L13,M13,N13,O13,P13,Q13,R13),"") -> 8 | U13: 6
C14: 8 | D14: Алимбаев Максат | K14: =IF(RIGHT(P49,1)="W",$M$4&":0(W)",IF(RIGHT(P49,1)="L","0:"&$M$4&"(L)",IF(P49="","",RIGHT(P49,1)&":"&LEFT(P49,1)))) | L14: =IF(LEFT(P54,1)="W",$M$4&":0(W)",IF(LEFT(P54,1)="L","0:"&$M$4&"(L)",IF(P54="","",P54))) -> 1:3 | N14: =IF(LEFT(P58,1)="W",$M$4&":0(W)",IF(LEFT(P58,1)="L","0:"&$M$4&"(L)",IF(P58="","",P58))) -> 0:3 | O14: =IF(LEFT(P34,1)="W",$M$4&":0(W)",IF(LEFT(P34,1)="L","0:"&$M$4&"(L)",IF(P34="","",P34))) -> 0:3 | P14: =IF(RIGHT(P48,1)="W",$M$4&":0(W)",IF(RIGHT(P48,1)="L","0:"&$M$4&"(L)",IF(P48="","",RIGHT(P48,1)&":"&LEFT(P48,1)))) -> 2:3 | Q14: =IF(LEFT(P44,1)="W",$M$4&":0(W)",IF(LEFT(P44,1)="L","0:"&$M$4&"(L)",IF(P44="","",P44))) -> 3:2 | R14: =IF(RIGHT(P39,1)="W",$M$4&":0(W)",IF(RIGHT(P39,1)="L","0:"&$M$4&"(L)",IF(P39="","",RIGHT(P39,1)&":"&LEFT(P39,1)))) -> 3:1
K15: =IF(P49="","",IF(Q49="","",REPLACE(SUBSTITUTE(SUBSTITUTE(SUBSTITUTE(SUBSTITUTE(","&Q49,",-","#"),",","-"),"#",","),"-",",-"),1,1,""))) | L15: =IF(P54="","",IF(Q54="","",Q54)) | N15: =IF(P58="","",IF(Q58="","",Q58)) | O15: =IF(P34="","",IF(Q34="","",Q34)) | P15: =IF(P48="","",IF(Q48="","",REPLACE(SUBSTITUTE(SUBSTITUTE(SUBSTITUTE(SUBSTITUTE(","&Q48,",-","#"),",","-"),"#",","),"-",",-"),1,1,""))) | Q15: =IF(P44="","",IF(Q44="","",Q44)) | R15: =IF(P39="","",IF(Q39="","",REPLACE(SUBSTITUTE(SUBSTITUTE(SUBSTITUTE(SUBSTITUTE(","&Q39,",-","#"),",","-"),"#",","),"-",",-"),1,1,"")))
G16: 4 | H16: КМС | I16: 28 | J16: Тажиев Нурсултан+ | K16: =IF(LEFT(P53,1)="L",0,(IF(P53="","",(IF(LEFT(P53,1)>RIGHT(P53,1),2,1))))) | L16: =IF(RIGHT(P50,1)="L",0,(IF(P50="","",(IF(RIGHT(P50,1)>LEFT(P50,1),2,1))))) -> 1 | M16: =IF(RIGHT(P58,1)="L",0,(IF(P58="","",(IF(RIGHT(P58,1)>LEFT(P58,1),2,1))))) -> 2 | O16: =IF(RIGHT(P46,1)="L",0,(IF(P46="","",(IF(RIGHT(P46,1)>LEFT(P46,1),2,1))))) -> 1 | P16: =IF(LEFT(P43,1)="L",0,(IF(P43="","",(IF(LEFT(P43,1)>RIGHT(P43,1),2,1))))) -> 2 | Q16: =IF(RIGHT(P40,1)="L",0,(IF(P40="","",(IF(RIGHT(P40,1)>LEFT(P40,1),2,1))))) -> 2 | R16: =IF(LEFT(P36,1)="L",0,(IF(P36="","",(IF(LEFT(P36,1)>RIGHT(P36,1),2,1))))) -> 1 | S16: =IF((AND(COUNTIF(J7:J30,">""")>2,COUNTIF(P33:P60,">""")>0)),SUM(K16,L16,M16,N16,O16,P16,Q16,R16),"") -> 9 | U16: 4
K17: =IF(LEFT(P53,1)="W",$M$4&":0(W)",IF(LEFT(P53,1)="L","0:"&$M$4&"(L)",IF(P53="","",P53))) | L17: =IF(RIGHT(P50,1)="W",$M$4&":0(W)",IF(RIGHT(P50,1)="L","0:"&$M$4&"(L)",IF(P50="","",RIGHT(P50,1)&":"&LEFT(P50,1)))) -> 1:3 | M17: =IF(RIGHT(P58,1)="W",$M$4&":0(W)",IF(RIGHT(P58,1)="L","0:"&$M$4&"(L)",IF(P58="","",RIGHT(P58,1)&":"&LEFT(P58,1)))) -> 3:0 | O17: =IF(RIGHT(P46,1)="W",$M$4&":0(W)",IF(RIGHT(P46,1)="L","0:"&$M$4&"(L)",IF(P46="","",RIGHT(P46,1)&":"&LEFT(P46,1)))) -> 1:3 | P17: =IF(LEFT(P43,1)="W",$M$4&":0(W)",IF(LEFT(P43,1)="L","0:"&$M$4&"(L)",IF(P43="","",P43))) -> 3:1 | Q17: =IF(RIGHT(P40,1)="W",$M$4&":0(W)",IF(RIGHT(P40,1)="L","0:"&$M$4&"(L)",IF(P40="","",RIGHT(P40,1)&":"&LEFT(P40,1)))) -> 3:2 | R17: =IF(LEFT(P36,1)="W",$M$4&":0(W)",IF(LEFT(P36,1)="L","0:"&$M$4&"(L)",IF(P36="","",P36))) -> 2:3
K18: =IF(P53="","",IF(Q53="","",Q53)) | L18: =IF(P50="","",IF(Q50="","",REPLACE(SUBSTITUTE(SUBSTITUTE(SUBSTITUTE(SUBSTITUTE(","&Q50,",-","#"),",","-"),"#",","),"-",",-"),1,1,""))) | M18: =IF(P58="","",IF(Q58="","",REPLACE(SUBSTITUTE(SUBSTITUTE(SUBSTITUTE(SUBSTITUTE(","&Q58,",-","#"),",","-"),"#",","),"-",",-"),1,1,""))) | O18: =IF(P46="","",IF(Q46="","",REPLACE(SUBSTITUTE(SUBSTITUTE(SUBSTITUTE(SUBSTITUTE(","&Q46,",-","#"),",","-"),"#",","),"-",",-"),1,1,""))) | P18: =IF(P43="","",IF(Q43="","",Q43)) | Q18: =IF(P40="","",IF(Q40="","",REPLACE(SUBSTITUTE(SUBSTITUTE(SUBSTITUTE(SUBSTITUTE(","&Q40,",-","#"),",","-"),"#",","),"-",",-"),1,1,""))) | R18: =IF(P36="","",IF(Q36="","",Q36))
G19: 5 | H19: МС | I19: 35 | J19: Суртубаев Марат+ | K19: =IF(RIGHT(P41,1)="L",0,(IF(P41="","",(IF(RIGHT(P41,1)>LEFT(P41,1),2,1))))) | L19: =IF(LEFT(P37,1)="L",0,(IF(P37="","",(IF(LEFT(P37,1)>RIGHT(P37,1),2,1))))) -> 2 | M19: =IF(RIGHT(P34,1)="L",0,(IF(P34="","",(IF(RIGHT(P34,1)>LEFT(P34,1),2,1))))) -> 2 | N19: =IF(LEFT(P46,1)="L",0,(IF(P46="","",(IF(LEFT(P46,1)>RIGHT(P46,1),2,1))))) -> 2 | P19: =IF(LEFT(P59,1)="L",0,(IF(P59="","",(IF(LEFT(P59,1)>RIGHT(P59,1),2,1))))) -> 2 | Q19: =IF(LEFT(P51,1)="L",0,(IF(P51="","",(IF(LEFT(P51,1)>RIGHT(P51,1),2,1))))) -> 2 | R19: =IF(RIGHT(P56,1)="L",0,(IF(P56="","",(IF(RIGHT(P56,1)>LEFT(P56,1),2,1))))) -> 2 | S19: =IF((AND(COUNTIF(J7:J30,">""")>2,COUNTIF(P33:P60,">""")>0)),SUM(K19,L19,M19,N19,O19,P19,Q19,R19),"") -> 12 | U19: 1
K20: =IF(RIGHT(P41,1)="W",$M$4&":0(W)",IF(RIGHT(P41,1)="L","0:"&$M$4&"(L)",IF(P41="","",RIGHT(P41,1)&":"&LEFT(P41,1)))) | L20: =IF(LEFT(P37,1)="W",$M$4&":0(W)",IF(LEFT(P37,1)="L","0:"&$M$4&"(L)",IF(P37="","",P37))) -> 3:2 | M20: =IF(RIGHT(P34,1)="W",$M$4&":0(W)",IF(RIGHT(P34,1)="L","0:"&$M$4&"(L)",IF(P34="","",RIGHT(P34,1)&":"&LEFT(P34,1)))) -> 3:0 | N20: =IF(LEFT(P46,1)="W",$M$4&":0(W)",IF(LEFT(P46,1)="L","0:"&$M$4&"(L)",IF(P46="","",P46))) -> 3:1 | P20: =IF(LEFT(P59,1)="W",$M$4&":0(W)",IF(LEFT(P59,1)="L","0:"&$M$4&"(L)",IF(P59="","",P59))) -> 3:1 | Q20: =IF(LEFT(P51,1)="W",$M$4&":0(W)",IF(LEFT(P51,1)="L","0:"&$M$4&"(L)",IF(P51="","",P51))) -> 3:0 | R20: =IF(RIGHT(P56,1)="W",$M$4&":0(W)",IF(RIGHT(P56,1)="L","0:"&$M$4&"(L)",IF(P56="","",RIGHT(P56,1)&":"&LEFT(P56,1)))) -> 3:1
K21: =IF(P41="","",IF(Q41="","",REPLACE(SUBSTITUTE(SUBSTITUTE(SUBSTITUTE(SUBSTITUTE(","&Q41,",-","#"),",","-"),"#",","),"-",",-"),1,1,""))) | L21: =IF(P37="","",IF(Q37="","",Q37)) | M21: =IF(P34="","",IF(Q34="","",REPLACE(SUBSTITUTE(SUBSTITUTE(SUBSTITUTE(SUBSTITUTE(","&Q34,",-","#"),",","-"),"#",","),"-",",-"),1,1,""))) | N21: =IF(P46="","",IF(Q46="","",Q46)) | P21: =IF(P59="","",IF(Q59="","",Q59)) | Q21: =IF(P51="","",IF(Q51="","",Q51)) | R21: =IF(P56="","",IF(Q56="","",REPLACE(SUBSTITUTE(SUBSTITUTE(SUBSTITUTE(SUBSTITUTE(","&Q56,",-","#"),",","-"),"#",","),"-",",-"),1,1,"")))
B22: 3:0 | G22: 6 | H22: КМС | I22: 20 | J22: Нурмухамет Данияр+ | K22: =IF(LEFT(P38,1)="L",0,(IF(P38="","",(IF(LEFT(P38,1)>RIGHT(P38,1),2,1))))) | L22: =IF(RIGHT(P33,1)="L",0,(IF(P33="","",(IF(RIGHT(P33,1)>LEFT(P33,1),2,1))))) -> 1 | M22: =IF(LEFT(P48,1)="L",0,(IF(P48="","",(IF(LEFT(P48,1)>RIGHT(P48,1),2,1))))) -> 2 | N22: =IF(RIGHT(P43,1)="L",0,(IF(P43="","",(IF(RIGHT(P43,1)>LEFT(P43,1),2,1))))) -> 1 | O22: =IF(RIGHT(P59,1)="L",0,(IF(P59="","",(IF(RIGHT(P59,1)>LEFT(P59,1),2,1))))) -> 1 | Q22: =IF(RIGHT(P55,1)="L",0,(IF(P55="","",(IF(RIGHT(P55,1)>LEFT(P55,1),2,1))))) -> 2 | R22: =IF(LEFT(P52,1)="L",0,(IF(P52="","",(IF(LEFT(P52,1)>RIGHT(P52,1),2,1))))) -> 1 | S22: =IF((AND(COUNTIF(J7:J30,">""")>2,COUNTIF(P33:P60,">""")>0)),SUM(K22,L22,M22,N22,O22,P22,Q22,R22),"") -> 8 | U22: 5
B23: 3:1 | K23: =IF(LEFT(P38,1)="W",$M$4&":0(W)",IF(LEFT(P38,1)="L","0:"&$M$4&"(L)",IF(P38="","",P38))) | L23: =IF(RIGHT(P33,1)="W",$M$4&":0(W)",IF(RIGHT(P33,1)="L","0:"&$M$4&"(L)",IF(P33="","",RIGHT(P33,1)&":"&LEFT(P33,1)))) -> 1:3 | M23: =IF(LEFT(P48,1)="W",$M$4&":0(W)",IF(LEFT(P48,1)="L","0:"&$M$4&"(L)",IF(P48="","",P48))) -> 3:2 | N23: =IF(RIGHT(P43,1)="W",$M$4&":0(W)",IF(RIGHT(P43,1)="L","0:"&$M$4&"(L)",IF(P43="","",RIGHT(P43,1)&":"&LEFT(P43,1)))) -> 1:3 | O23: =IF(RIGHT(P59,1)="W",$M$4&":0(W)",IF(RIGHT(P59,1)="L","0:"&$M$4&"(L)",IF(P59="","",RIGHT(P59,1)&":"&LEFT(P59,1)))) -> 1:3 | Q23: =IF(RIGHT(P55,1)="W",$M$4&":0(W)",IF(RIGHT(P55,1)="L","0:"&$M$4&"(L)",IF(P55="","",RIGHT(P55,1)&":"&LEFT(P55,1)))) -> 3:0 | R23: =IF(LEFT(P52,1)="W",$M$4&":0(W)",IF(LEFT(P52,1)="L","0:"&$M$4&"(L)",IF(P52="","",P52))) -> 2:3
B24: 3:2 | K24: =IF(P38="","",IF(Q38="","",Q38)) | L24: =IF(P33="","",IF(Q33="","",REPLACE(SUBSTITUTE(SUBSTITUTE(SUBSTITUTE(SUBSTITUTE(","&Q33,",-","#"),",","-"),"#",","),"-",",-"),1,1,""))) | M24: =IF(P48="","",IF(Q48="","",Q48)) | N24: =IF(P43="","",IF(Q43="","",REPLACE(SUBSTITUTE(SUBSTITUTE(SUBSTITUTE(SUBSTITUTE(","&Q43,",-","#"),",","-"),"#",","),"-",",-"),1,1,""))) | O24: =IF(P59="","",IF(Q59="","",REPLACE(SUBSTITUTE(SUBSTITUTE(SUBSTITUTE(SUBSTITUTE(","&Q59,",-","#"),",","-"),"#",","),"-",",-"),1,1,""))) | Q24: =IF(P55="","",IF(Q55="","",REPLACE(SUBSTITUTE(SUBSTITUTE(SUBSTITUTE(SUBSTITUTE(","&Q55,",-","#"),",","-"),"#",","),"-",",-"),1,1,""))) | R24: =IF(P52="","",IF(Q52="","",Q52))
B25: 0:3 | G25: 7 | I25: 21 | J25: Утельбеков Ермек+ | K25: =IF(RIGHT(P35,1)="L",0,(IF(P35="","",(IF(RIGHT(P35,1)>LEFT(P35,1),2,1))))) | L25: =IF(LEFT(P47,1)="L",0,(IF(P47="","",(IF(LEFT(P47,1)>RIGHT(P47,1),2,1))))) -> 1 | M25: =IF(RIGHT(P44,1)="L",0,(IF(P44="","",(IF(RIGHT(P44,1)>LEFT(P44,1),2,1))))) -> 1 | N25: =IF(LEFT(P40,1)="L",0,(IF(P40="","",(IF(LEFT(P40,1)>RIGHT(P40,1),2,1))))) -> 1 | O25: =IF(RIGHT(P51,1)="L",0,(IF(P51="","",(IF(RIGHT(P51,1)>LEFT(P51,1),2,1))))) -> 1 | P25: =IF(LEFT(P55,1)="L",0,(IF(P55="","",(IF(LEFT(P55,1)>RIGHT(P55,1),2,1))))) -> 1 | R25: =IF(LEFT(P60,1)="L",0,(IF(P60="","",(IF(LEFT(P60,1)>RIGHT(P60,1),2,1))))) -> 0 | S25: =IF((AND(COUNTIF(J7:J30,">""")>2,COUNTIF(P33:P60,">""")>0)),SUM(K25,L25,M25,N25,O25,P25,Q25,R25),"") -> 5 | U25: 7
B26: 1:3 | K26: =IF(RIGHT(P35,1)="W",$M$4&":0(W)",IF(RIGHT(P35,1)="L","0:"&$M$4&"(L)",IF(P35="","",RIGHT(P35,1)&":"&LEFT(P35,1)))) | L26: =IF(LEFT(P47)="W",$M$4&":0(W)",IF(LEFT(P47,1)="L","0:"&$M$4&"(L)",IF(P47="","",P47))) -> 0:3 | M26: =IF(RIGHT(P44,1)="W",$M$4&":0(W)",IF(RIGHT(P44,1)="L","0:"&$M$4&"(L)",IF(P44="","",RIGHT(P44,1)&":"&LEFT(P44,1)))) -> 2:3 | N26: =IF(LEFT(P40,1)="W",$M$4&":0(W)",IF(LEFT(P40,1)="L","0:"&$M$4&"(L)",IF(P40="","",P40))) -> 2:3 | O26: =IF(RIGHT(P51,1)="W",$M$4&":0(W)",IF(RIGHT(P51,1)="L","0:"&$M$4&"(L)",IF(P51="","",RIGHT(P51,1)&":"&LEFT(P51,1)))) -> 0:3 | P26: =IF(LEFT(P55,1)="W",$M$4&":0(W)",IF(LEFT(P55,1)="L","0:"&$M$4&"(L)",IF(P55="","",P55))) -> 0:3 | R26: =IF(LEFT(P60,1)="W",$M$4&":0(W)",IF(LEFT(P60,1)="L","0:"&$M$4&"(L)",IF(P60="","",P60))) -> 0:3(L)
B27: 2:3 | K27: =IF(P35="","",IF(Q35="","",REPLACE(SUBSTITUTE(SUBSTITUTE(SUBSTITUTE(SUBSTITUTE(","&Q35,",-","#"),",","-"),"#",","),"-",",-"),1,1,""))) | L27: =IF(P47="","",IF(Q47="","",Q47)) | M27: =IF(P44="","",IF(Q44="","",REPLACE(SUBSTITUTE(SUBSTITUTE(SUBSTITUTE(SUBSTITUTE(","&Q44,",-","#"),",","-"),"#",","),"-",",-"),1,1,""))) | N27: =IF(P40="","",IF(Q40="","",Q40)) | O27: =IF(P51="","",IF(Q51="","",REPLACE(SUBSTITUTE(SUBSTITUTE(SUBSTITUTE(SUBSTITUTE(","&Q51,",-","#"),",","-"),"#",","),"-",",-"),1,1,""))) | P27: =IF(P55="","",IF(Q55="","",Q55)) | R27: =IF(P60="","",IF(Q60="","",Q60))
B28: W:L | G28: 8 | H28: КМС | I28: 26 | J28: Алимбаев Максат+ | K28: =IF(LEFT(P45,1)="L",0,(IF(P45="","",(IF(LEFT(P45,1)>RIGHT(P45,1),2,1))))) | L28: =IF(RIGHT(P42,1)="L",0,(IF(P42="","",(IF(RIGHT(P42,1)>LEFT(P42,1),2,1))))) -> 2 | M28: =IF(LEFT(P39,1)="L",0,(IF(P39="","",(IF(LEFT(P39,1)>RIGHT(P39,1),2,1))))) -> 1 | N28: =IF(RIGHT(P36,1)="L",0,(IF(P36="","",(IF(RIGHT(P36,1)>LEFT(P36,1),2,1))))) -> 2 | O28: =IF(LEFT(P56,1)="L",0,(IF(P56="","",(IF(LEFT(P56,1)>RIGHT(P56,1),2,1))))) -> 1 | P28: =IF(RIGHT(P52,1)="L",0,(IF(P52="","",(IF(RIGHT(P52,1)>LEFT(P52,1),2,1))))) -> 2 | Q28: =IF(RIGHT(P60,1)="L",0,(IF(P60="","",(IF(RIGHT(P60,1)>LEFT(P60,1),2,1))))) -> 2 | S28: =IF((AND(COUNTIF(J7:J30,">""")>2,COUNTIF(P33:P60,">""")>0)),SUM(K28,L28,M28,N28,O28,P28,Q28,R28),"") -> 10 | U28: 2
B29: L:W | K29: =IF(LEFT(P45,1)="W",$M$4&":0(W)",IF(LEFT(P45,1)="L","0:"&$M$4&"(L)",IF(P45="","",P45))) | L29: =IF(RIGHT(P42,1)="W",$M$4&":0(W)",IF(RIGHT(P42,1)="L","0:"&$M$4&"(L)",IF(P42="","",RIGHT(P42,1)&":"&LEFT(P42,1)))) -> 3:1 | M29: =IF(LEFT(P39,1)="W",$M$4&":0(W)",IF(LEFT(P39,1)="L","0:"&$M$4&"(L)",IF(P39="","",P39))) -> 1:3 | N29: =IF(RIGHT(P36,1)="W",$M$4&":0(W)",IF(RIGHT(P36,1)="L","0:"&$M$4&"(L)",IF(P36="","",RIGHT(P36,1)&":"&LEFT(P36,1)))) -> 3:2 | O29: =IF(LEFT(P56,1)="W",$M$4&":0(W)",IF(LEFT(P56,1)="L","0:"&$M$4&"(L)",IF(P56="","",P56))) -> 1:3 | P29: =IF(RIGHT(P52,1)="W",$M$4&":0(W)",IF(RIGHT(P52,1)="L","0:"&$M$4&"(L)",IF(P52="","",RIGHT(P52,1)&":"&LEFT(P52,1)))) -> 3:2 | Q29: =IF(RIGHT(P60,1)="W",$M$4&":0(W)",IF(RIGHT(P60,1)="L","0:"&$M$4&"(L)",IF(P60="","",RIGHT(P60,1)&":"&LEFT(P60,1)))) -> 3:0(W)
B30: 2:0 | K30: =IF(P45="","",IF(Q45="","",Q45)) | L30: =IF(P42="","",IF(Q42="","",REPLACE(SUBSTITUTE(SUBSTITUTE(SUBSTITUTE(SUBSTITUTE(","&Q42,",-","#"),",","-"),"#",","),"-",",-"),1,1,""))) | M30: =IF(P39="","",IF(Q39="","",Q39)) | N30: =IF(P36="","",IF(Q36="","",REPLACE(SUBSTITUTE(SUBSTITUTE(SUBSTITUTE(SUBSTITUTE(","&Q36,",-","#"),",","-"),"#",","),"-",",-"),1,1,""))) | O30: =IF(P56="","",IF(Q56="","",Q56)) | P30: =IF(P52="","",IF(Q52="","",REPLACE(SUBSTITUTE(SUBSTITUTE(SUBSTITUTE(SUBSTITUTE(","&Q52,",-","#"),",","-"),"#",","),"-",",-"),1,1,""))) | Q30: =IF(P60="","",IF(Q60="","",REPLACE(SUBSTITUTE(SUBSTITUTE(SUBSTITUTE(SUBSTITUTE(","&Q60,",-","#"),",","-"),"#",","),"-",",-"),1,1,"")))
B31: 2:1
B32: 1:2 | I32: ю | P32: счет по сетам | Q32: мячи
B33: 0:2 | G33: 1 круг | I33: 9 | J33: =IF(А1!Уч2="","",А1!Уч2) -> Токтамыс Нурбол+ | K33: ="-" -> - | L33: =IF(А1!Уч6="","",А1!Уч6) -> Нурмухамет Данияр+ | P33: 3:1 | S33: =IF(AND(I33<>"",P33=""),"встреча играется",IF(P33<>"","сыграна","")) -> сыграна
B34: 4:0 | I34: 13 | J34: =IF(А1!Уч3="","",А1!Уч3) -> Ибраев Ерлан+ | K34: ="-" -> - | L34: =IF(А1!Уч5="","",А1!Уч5) -> Суртубаев Марат+ | P34: 0:3 | S34: =IF(AND(I34<>"",P34=""),"встреча играется",IF(P34<>"","сыграна","")) -> сыграна
B35: 4:1 | J35: =IF(А1!Уч1="","",А1!Уч1) -> Дуйсенбай Есенали | K35: ="-" -> - | L35: =IF(А1!Уч7="","",А1!Уч7) -> Утельбеков Ермек+ | S35: =IF(AND(I35<>"",P35=""),"встреча играется",IF(P35<>"","сыграна",""))
B36: 4:2 | I36: 14 | J36: =IF(А1!Уч4="","",А1!Уч4) -> Тажиев Нурсултан+ | K36: ="-" -> - | L36: =IF(А1!Уч8="","",А1!Уч8) -> Алимбаев Максат+ | P36: 2:3 | S36: =IF(AND(I36<>"",P36=""),"встреча играется",IF(P36<>"","сыграна","")) -> сыграна
B37: 4:3 | G37: 2 круг | I37: 9 | J37: =IF(А1!Уч5="","",А1!Уч5) -> Суртубаев Марат+ | K37: ="-" -> - | L37: =IF(А1!Уч2="","",А1!Уч2) -> Токтамыс Нурбол+ | P37: 3:2 | S37: =IF(AND(I37<>"",P37=""),"встреча играется",IF(P37<>"","сыграна","")) -> сыграна
B38: 0:4 | J38: =IF(А1!Уч6="","",А1!Уч6) -> Нурмухамет Данияр+ | K38: ="-" -> - | L38: =IF(А1!Уч1="","",А1!Уч1) -> Дуйсенбай Есенали | S38: =IF(AND(I38<>"",P38=""),"встреча играется",IF(P38<>"","сыграна",""))
B39: 1:4 | I39: 12 | J39: =IF(А1!Уч8="","",А1!Уч8) -> Алимбаев Максат+ | K39: ="-" -> - | L39: =IF(А1!Уч3="","",А1!Уч3) -> Ибраев Ерлан+ | P39: 1:3 | S39: =IF(AND(I39<>"",P39=""),"встреча играется",IF(P39<>"","сыграна","")) -> сыграна
B40: 2:4 | I40: 14 | J40: =IF(А1!Уч7="","",А1!Уч7) -> Утельбеков Ермек+ | K40: ="-" -> - | L40: =IF(А1!Уч4="","",А1!Уч4) -> Тажиев Нурсултан+ | P40: 2:3 | S40: =IF(AND(I40<>"",P40=""),"встреча играется",IF(P40<>"","сыграна","")) -> сыграна
B41: 3:4 | G41: 3 круг | J41: =IF(А1!Уч1="","",А1!Уч1) -> Дуйсенбай Есенали | K41: ="-" -> - | L41: =IF(А1!Уч5="","",А1!Уч5) -> Суртубаев Марат+ | S41: =IF(AND(I41<>"",P41=""),"встреча играется",IF(P41<>"","сыграна",""))
I42: 12 | J42: =IF(А1!Уч2="","",А1!Уч2) -> Токтамыс Нурбол+ | K42: ="-" -> - | L42: =IF(А1!Уч8="","",А1!Уч8) -> Алимбаев Максат+ | P42: 1:3 | S42: =IF(AND(I42<>"",P42=""),"встреча играется",IF(P42<>"","сыграна","")) -> сыграна
...

Sheet А2
D1: Турнир Открытое первенство города Астана (лиги) | K1: Дата: | L1: =Суперлига!L1 -> 46033
K4: матчи до | M4: 3 | N4: побед
C5: =IF(COUNTIF(D7:D14,"")>0,1,0) -> 0 | E5: =IF((COUNTIF(L33:R60,">""")+COUNTIF(T7:U30,">"""))>0,1,0) -> 1
C6: № | D6: Участники турнира | E6: Рейтинг | G6: № | H6: Разряд | I6: R | J6: Фамилия Имя | K6: 1 | L6: 2 | M6: 3 | N6: 4 | O6: 5 | P6: 6 | Q6: 7 | R6: 8 | S6: Очки | T6: Соотн. | U6: Место
C7: 1 | D7: Овчинников Евгений | G7: 1 | H7: КМС | I7: 22 | J7: Овчинников Евгений+ | L7: =IF(LEFT(P57,1)="L",0,(IF(P57="","",(IF(LEFT(P57,1)>RIGHT(P57,1),2,1))))) -> 1 | M7: =IF(LEFT(P49,1)="L",0,(IF(P49="","",(IF(LEFT(P49,1)>RIGHT(P49,1),2,1))))) -> 1 | N7: =IF(RIGHT(P53,1)="L",0,(IF(P53="","",(IF(RIGHT(P53,1)>LEFT(P53,1),2,1))))) -> 2 | O7: =IF(LEFT(P41,1)="L",0,(IF(P41="","",(IF(LEFT(P41,1)>RIGHT(P41,1),2,1))))) -> 2 | P7: =IF(RIGHT(P38,1)="L",0,(IF(P38="","",(IF(RIGHT(P38,1)>LEFT(P38,1),2,1))))) -> 2 | Q7: =IF(LEFT(P35,1)="L",0,(IF(P35="","",(IF(LEFT(P35,1)>RIGHT(P35,1),2,1))))) -> 2 | R7: =IF(RIGHT(P45,1)="L",0,(IF(P45="","",(IF(RIGHT(P45,1)>LEFT(P45,1),2,1))))) -> 1 | S7: =IF((AND(COUNTIF(J7:J30,">""")>2,COUNTIF(P33:P60,">""")>0)),SUM(K7,L7,M7,N7,O7,P7,Q7,R7),"") -> 11 | U7: 4
C8: 2 | D8: Пак Данил | L8: =IF(LEFT(P57,1)="W",$M$4&":0(W)",IF(LEFT(P57,1)="L","0:"&$M$4&"(L)",IF(P57="","",P57))) -> 1:3 | M8: =IF(LEFT(P49,1)="W",$M$4&":0(W)",IF(LEFT(P49,1)="L","0:"&$M$4&"(L)",IF(P49="","",P49))) -> 1:3 | N8: =IF(RIGHT(P53,1)="W",$M$4&":0(W)",IF(RIGHT(P53,1)="L","0:"&$M$4&"(L)",IF(P53="","",RIGHT(P53,1)&":"&LEFT(P53,1)))) -> 3:2 | O8: =IF(LEFT(P41,1)="W",$M$4&":0(W)",IF(LEFT(P41,1)="L","0:"&$M$4&"(L)",IF(P41="","",P41))) -> 3:1 | P8: =IF(RIGHT(P38,1)="W",$M$4&":0(W)",IF(RIGHT(P38,1)="L","0:"&$M$4&"(L)",IF(P38="","",RIGHT(P38,1)&":"&LEFT(P38,1)))) -> 3:2 | Q8: =IF(LEFT(P35,1)="W",$M$4&":0(W)",IF(LEFT(P35,1)="L","0:"&$M$4&"(L)",IF(P35="","",P35))) -> 3:2 | R8: =IF(RIGHT(P45,1)="W",$M$4&":0(W)",IF(RIGHT(P45,1)="L","0:"&$M$4&"(L)",IF(P45="","",RIGHT(P45,1)&":"&LEFT(P45,1)))) -> 0:3
C9: 3 | D9: Садыков Алмаз | L9: =IF(P57="","",IF(Q57="","",Q57)) | M9: =IF(P49="","",IF(Q49="","",Q49)) | N9: =IF(P53="","",IF(Q53="","",REPLACE(SUBSTITUTE(SUBSTITUTE(SUBSTITUTE(SUBSTITUTE(","&Q53,",-","#"),",","-"),"#",","),"-",",-"),1,1,""))) | O9: =IF(P41="","",IF(Q41="","",Q41)) | P9: =IF(P38="","",IF(Q38="","",REPLACE(SUBSTITUTE(SUBSTITUTE(SUBSTITUTE(SUBSTITUTE(","&Q38,",-","#"),",","-"),"#",","),"-",",-"),1,1,""))) | Q9: =IF(P35="","",IF(Q35="","",Q35)) | R9: =IF(P45="","",IF(Q45="","",REPLACE(SUBSTITUTE(SUBSTITUTE(SUBSTITUTE(SUBSTITUTE(","&Q45,",-","#"),",","-"),"#",","),"-",",-"),1,1,"")))
C10: 4 | D10: Шакар Ерасыл | G10: 2 | H10: МС | I10: 34 | J10: Пак Данил+ | K10: =IF(RIGHT(P57,1)="L",0,(IF(P57="","",(IF(RIGHT(P57,1)>LEFT(P57,1),2,1))))) -> 2 | M10: =IF(RIGHT(P54,1)="L",0,(IF(P54="","",(IF(RIGHT(P54,1)>LEFT(P54,1),2,1))))) -> 1 | N10: =IF(LEFT(P50,1)="L",0,(IF(P50="","",(IF(LEFT(P50,1)>RIGHT(P50,1),2,1))))) -> 2 | O10: =IF(RIGHT(P37,1)="L",0,(IF(P37="","",(IF(RIGHT(P37,1)>LEFT(P37,1),2,1))))) -> 2 | P10: =IF(LEFT(P33,1)="L",0,(IF(P33="","",(IF(LEFT(P33,1)>RIGHT(P33,1),2,1))))) -> 1 | Q10: =IF(RIGHT(P47,1)="L",0,(IF(P47="","",(IF(RIGHT(P47,1)>LEFT(P47,1),2,1))))) -> 2 | R10: =IF(LEFT(P42,1)="L",0,(IF(P42="","",(IF(LEFT(P42,1)>RIGHT(P42,1),2,1))))) -> 2 | S10: =IF((AND(COUNTIF(J7:J30,">""")>2,COUNTIF(P33:P60,">""")>0)),SUM(K10,L10,M10,N10,O10,P10,Q10,R10),"") -> 12 | U10: 3
C11: 5 | D11: Капышев Нуржан | K11: =IF(RIGHT(P57,1)="W",$M$4&":0(W)",IF(RIGHT(P57,1)="L","0:"&$M$4&"(L)",IF(P57="","",RIGHT(P57,1)&":"&LEFT(P57,1)))) -> 3:1 | M11: =IF(RIGHT(P54,1)="W",$M$4&":0(W)",IF(RIGHT(P54,1)="L","0:"&$M$4&"(L)",IF(P54="","",RIGHT(P54,1)&":"&LEFT(P54,1)))) -> 0:3 | N11: =IF(LEFT(P50,1)="W",$M$4&":0(W)",IF(LEFT(P50,1)="L","0:"&$M$4&"(L)",IF(P50="","",P50))) -> 3:1 | O11: =IF(RIGHT(P37,1)="W",$M$4&":0(W)",IF(RIGHT(P37,1)="L","0:"&$M$4&"(L)",IF(P37="","",RIGHT(P37,1)&":"&LEFT(P37,1)))) -> 3:1 | P11: =IF(LEFT(P33,1)="W",$M$4&":0(W)",IF(LEFT(P33,1)="L","0:"&$M$4&"(L)",IF(P33="","",P33))) -> 2:3 | Q11: =IF(RIGHT(P47,1)="W",$M$4&":0(W)",IF(RIGHT(P47,1)="L","0:"&$M$4&"(L)",IF(P47="","",RIGHT(P47,1)&":"&LEFT(P47,1)))) -> 3:2 | R11: =IF(LEFT(P42,1)="W",$M$4&":0(W)",IF(LEFT(P42,1)="L","0:"&$M$4&"(L)",IF(P42="","",P42))) -> 3:0
C12: 6 | D12: Куанышбеков Алмат | K12: =IF(P57="","",IF(Q57="","",REPLACE(SUBSTITUTE(SUBSTITUTE(SUBSTITUTE(SUBSTITUTE(","&Q57,",-","#"),",","-"),"#",","),"-",",-"),1,1,""))) | M12: =IF(P54="","",IF(Q54="","",REPLACE(SUBSTITUTE(SUBSTITUTE(SUBSTITUTE(SUBSTITUTE(","&Q54,",-","#"),",","-"),"#",","),"-",",-"),1,1,""))) | N12: =IF(P50="","",IF(Q50="","",Q50)) | O12: =IF(P37="","",IF(Q37="","",REPLACE(SUBSTITUTE(SUBSTITUTE(SUBSTITUTE(SUBSTITUTE(","&Q37,",-","#"),",","-"),"#",","),"-",",-"),1,1,""))) | P12: =IF(P33="","",IF(Q33="","",Q33)) | Q12: =IF(P47="","",IF(Q47="","",REPLACE(SUBSTITUTE(SUBSTITUTE(SUBSTITUTE(SUBSTITUTE(","&Q47,",-","#"),",","-"),"#",","),"-",",-"),1,1,""))) | R12: =IF(P42="","",IF(Q42="","",Q42))
C13: 7 | D13: Боченин Игорь | G13: 3 | H13: МС | I13: 34 | J13: Садыков Алмаз+ | K13: =IF(RIGHT(P49,1)="L",0,(IF(P49="","",(IF(RIGHT(P49,1)>LEFT(P49,1),2,1))))) -> 2 | L13: =IF(LEFT(P54,1)="L",0,(IF(P54="","",(IF(LEFT(P54,1)>RIGHT(P54,1),2,1))))) -> 2 | N13: =IF(LEFT(P58,1)="L",0,(IF(P58="","",(IF(LEFT(P58,1)>RIGHT(P58,1),2,1))))) -> 2 | O13: =IF(LEFT(P34,1)="L",0,(IF(P34="","",(IF(LEFT(P34,1)>RIGHT(P34,1),2,1))))) -> 2 | P13: =IF(RIGHT(P48,1)="L",0,(IF(P48="","",(IF(RIGHT(P48,1)>LEFT(P48,1),2,1))))) -> 1 | Q13: =IF(LEFT(P44,1)="L",0,(IF(P44="","",(IF(LEFT(P44,1)>RIGHT(P44,1),2,1))))) -> 2 | R13: =IF(RIGHT(P39,1)="L",0,(IF(P39="","",(IF(RIGHT(P39,1)>LEFT(P39,1),2,1))))) -> 2 | S13: =IF((AND(COUNTIF(J7:J30,">""")>2,COUNTIF(P33:P60,">""")>0)),SUM(K13,L13,M13,N13,O13,P13,Q13,R13),"") -> 13 | U13: 1
C14: 8 | D14: Ердяков Роман | K14: =IF(RIGHT(P49,1)="W",$M$4&":0(W)",IF(RIGHT(P49,1)="L","0:"&$M$4&"(L)",IF(P49="","",RIGHT(P49,1)&":"&LEFT(P49,1)))) -> 3:1 | L14: =IF(LEFT(P54,1)="W",$M$4&":0(W)",IF(LEFT(P54,1)="L","0:"&$M$4&"(L)",IF(P54="","",P54))) -> 3:0 | N14: =IF(LEFT(P58,1)="W",$M$4&":0(W)",IF(LEFT(P58,1)="L","0:"&$M$4&"(L)",IF(P58="","",P58))) -> 3:1 | O14: =IF(LEFT(P34,1)="W",$M$4&":0(W)",IF(LEFT(P34,1)="L","0:"&$M$4&"(L)",IF(P34="","",P34))) -> 3:2 | P14: =IF(RIGHT(P48,1)="W",$M$4&":0(W)",IF(RIGHT(P48,1)="L","0:"&$M$4&"(L)",IF(P48="","",RIGHT(P48,1)&":"&LEFT(P48,1)))) -> 2:3 | Q14: =IF(LEFT(P44,1)="W",$M$4&":0(W)",IF(LEFT(P44,1)="L","0:"&$M$4&"(L)",IF(P44="","",P44))) -> 3:0 | R14: =IF(RIGHT(P39,1)="W",$M$4&":0(W)",IF(RIGHT(P39,1)="L","0:"&$M$4&"(L)",IF(P39="","",RIGHT(P39,1)&":"&LEFT(P39,1)))) -> 3:0
K15: =IF(P49="","",IF(Q49="","",REPLACE(SUBSTITUTE(SUBSTITUTE(SUBSTITUTE(SUBSTITUTE(","&Q49,",-","#"),",","-"),"#",","),"-",",-"),1,1,""))) | L15: =IF(P54="","",IF(Q54="","",Q54)) | N15: =IF(P58="","",IF(Q58="","",Q58)) | O15: =IF(P34="","",IF(Q34="","",Q34)) | P15: =IF(P48="","",IF(Q48="","",REPLACE(SUBSTITUTE(SUBSTITUTE(SUBSTITUTE(SUBSTITUTE(","&Q48,",-","#"),",","-"),"#",","),"-",",-"),1,1,""))) | Q15: =IF(P44="","",IF(Q44="","",Q44)) | R15: =IF(P39="","",IF(Q39="","",REPLACE(SUBSTITUTE(SUBSTITUTE(SUBSTITUTE(SUBSTITUTE(","&Q39,",-","#"),",","-"),"#",","),"-",",-"),1,1,"")))
G16: 4 | H16: КМС | I16: 19 | J16: Шакар Ерасыл+ | K16: =IF(LEFT(P53,1)="L",0,(IF(P53="","",(IF(LEFT(P53,1)>RIGHT(P53,1),2,1))))) -> 1 | L16: =IF(RIGHT(P50,1)="L",0,(IF(P50="","",(IF(RIGHT(P50,1)>LEFT(P50,1),2,1))))) -> 1 | M16: =IF(RIGHT(P58,1)="L",0,(IF(P58="","",(IF(RIGHT(P58,1)>LEFT(P58,1),2,1))))) -> 1 | O16: =IF(RIGHT(P46,1)="L",0,(IF(P46="","",(IF(RIGHT(P46,1)>LEFT(P46,1),2,1))))) -> 2 | P16: =IF(LEFT(P43,1)="L",0,(IF(P43="","",(IF(LEFT(P43,1)>RIGHT(P43,1),2,1))))) -> 1 | Q16: =IF(RIGHT(P40,1)="L",0,(IF(P40="","",(IF(RIGHT(P40,1)>LEFT(P40,1),2,1))))) -> 1 | R16: =IF(LEFT(P36,1)="L",0,(IF(P36="","",(IF(LEFT(P36,1)>RIGHT(P36,1),2,1))))) -> 2 | S16: =IF((AND(COUNTIF(J7:J30,">""")>2,COUNTIF(P33:P60,">""")>0)),SUM(K16,L16,M16,N16,O16,P16,Q16,R16),"") -> 9 | U16: 6
K17: =IF(LEFT(P53,1)="W",$M$4&":0(W)",IF(LEFT(P53,1)="L","0:"&$M$4&"(L)",IF(P53="","",P53))) -> 2:3 | L17: =IF(RIGHT(P50,1)="W",$M$4&":0(W)",IF(RIGHT(P50,1)="L","0:"&$M$4&"(L)",IF(P50="","",RIGHT(P50,1)&":"&LEFT(P50,1)))) -> 1:3 | M17: =IF(RIGHT(P58,1)="W",$M$4&":0(W)",IF(RIGHT(P58,1)="L","0:"&$M$4&"(L)",IF(P58="","",RIGHT(P58,1)&":"&LEFT(P58,1)))) -> 1:3 | O17: =IF(RIGHT(P46,1)="W",$M$4&":0(W)",IF(RIGHT(P46,1)="L","0:"&$M$4&"(L)",IF(P46="","",RIGHT(P46,1)&":"&LEFT(P46,1)))) -> 3:2 | P17: =IF(LEFT(P43,1)="W",$M$4&":0(W)",IF(LEFT(P43,1)="L","0:"&$M$4&"(L)",IF(P43="","",P43))) -> 2:3 | Q17: =IF(RIGHT(P40,1)="W",$M$4&":0(W)",IF(RIGHT(P40,1)="L","0:"&$M$4&"(L)",IF(P40="","",RIGHT(P40,1)&":"&LEFT(P40,1)))) -> 1:3 | R17: =IF(LEFT(P36,1)="W",$M$4&":0(W)",IF(LEFT(P36,1)="L","0:"&$M$4&"(L)",IF(P36="","",P36))) -> 3:0
K18: =IF(P53="","",IF(Q53="","",Q53)) | L18: =IF(P50="","",IF(Q50="","",REPLACE(SUBSTITUTE(SUBSTITUTE(SUBSTITUTE(SUBSTITUTE(","&Q50,",-","#"),",","-"),"#",","),"-",",-"),1,1,""))) | M18: =IF(P58="","",IF(Q58="","",REPLACE(SUBSTITUTE(SUBSTITUTE(SUBSTITUTE(SUBSTITUTE(","&Q58,",-","#"),",","-"),"#",","),"-",",-"),1,1,""))) | O18: =IF(P46="","",IF(Q46="","",REPLACE(SUBSTITUTE(SUBSTITUTE(SUBSTITUTE(SUBSTITUTE(","&Q46,",-","#"),",","-"),"#",","),"-",",-"),1,1,""))) | P18: =IF(P43="","",IF(Q43="","",Q43)) | Q18: =IF(P40="","",IF(Q40="","",REPLACE(SUBSTITUTE(SUBSTITUTE(SUBSTITUTE(SUBSTITUTE(","&Q40,",-","#"),",","-"),"#",","),"-",",-"),1,1,""))) | R18: =IF(P36="","",IF(Q36="","",Q36))
G19: 5 | I19: 19 | J19: Капышев Нуржан+ | K19: =IF(RIGHT(P41,1)="L",0,(IF(P41="","",(IF(RIGHT(P41,1)>LEFT(P41,1),2,1))))) -> 1 | L19: =IF(LEFT(P37,1)="L",0,(IF(P37="","",(IF(LEFT(P37,1)>RIGHT(P37,1),2,1))))) -> 1 | M19: =IF(RIGHT(P34,1)="L",0,(IF(P34="","",(IF(RIGHT(P34,1)>LEFT(P34,1),2,1))))) -> 1 | N19: =IF(LEFT(P46,1)="L",0,(IF(P46="","",(IF(LEFT(P46,1)>RIGHT(P46,1),2,1))))) -> 1 | P19: =IF(LEFT(P59,1)="L",0,(IF(P59="","",(IF(LEFT(P59,1)>RIGHT(P59,1),2,1))))) -> 1 | Q19: =IF(LEFT(P51,1)="L",0,(IF(P51="","",(IF(LEFT(P51,1)>RIGHT(P51,1),2,1))))) -> 0 | R19: =IF(RIGHT(P56,1)="L",0,(IF(P56="","",(IF(RIGHT(P56,1)>LEFT(P56,1),2,1))))) -> 1 | S19: =IF((AND(COUNTIF(J7:J30,">""")>2,COUNTIF(P33:P60,">""")>0)),SUM(K19,L19,M19,N19,O19,P19,Q19,R19),"") -> 6 | U19: 8
K20: =IF(RIGHT(P41,1)="W",$M$4&":0(W)",IF(RIGHT(P41,1)="L","0:"&$M$4&"(L)",IF(P41="","",RIGHT(P41,1)&":"&LEFT(P41,1)))) -> 1:3 | L20: =IF(LEFT(P37,1)="W",$M$4&":0(W)",IF(LEFT(P37,1)="L","0:"&$M$4&"(L)",IF(P37="","",P37))) -> 1:3 | M20: =IF(RIGHT(P34,1)="W",$M$4&":0(W)",IF(RIGHT(P34,1)="L","0:"&$M$4&"(L)",IF(P34="","",RIGHT(P34,1)&":"&LEFT(P34,1)))) -> 2:3 | N20: =IF(LEFT(P46,1)="W",$M$4&":0(W)",IF(LEFT(P46,1)="L","0:"&$M$4&"(L)",IF(P46="","",P46))) -> 2:3 | P20: =IF(LEFT(P59,1)="W",$M$4&":0(W)",IF(LEFT(P59,1)="L","0:"&$M$4&"(L)",IF(P59="","",P59))) -> 2:3 | Q20: =IF(LEFT(P51,1)="W",$M$4&":0(W)",IF(LEFT(P51,1)="L","0:"&$M$4&"(L)",IF(P51="","",P51))) -> 0:3(L) | R20: =IF(RIGHT(P56,1)="W",$M$4&":0(W)",IF(RIGHT(P56,1)="L","0:"&$M$4&"(L)",IF(P56="","",RIGHT(P56,1)&":"&LEFT(P56,1)))) -> 1:3
K21: =IF(P41="","",IF(Q41="","",REPLACE(SUBSTITUTE(SUBSTITUTE(SUBSTITUTE(SUBSTITUTE(","&Q41,",-","#"),",","-"),"#",","),"-",",-"),1,1,""))) | L21: =IF(P37="","",IF(Q37="","",Q37)) | M21: =IF(P34="","",IF(Q34="","",REPLACE(SUBSTITUTE(SUBSTITUTE(SUBSTITUTE(SUBSTITUTE(","&Q34,",-","#"),",","-"),"#",","),"-",",-"),1,1,""))) | N21: =IF(P46="","",IF(Q46="","",Q46)) | P21: =IF(P59="","",IF(Q59="","",Q59)) | Q21: =IF(P51="","",IF(Q51="","",Q51)) | R21: =IF(P56="","",IF(Q56="","",REPLACE(SUBSTITUTE(SUBSTITUTE(SUBSTITUTE(SUBSTITUTE(","&Q56,",-","#"),",","-"),"#",","),"-",",-"),1,1,"")))
B22: 3:0 | G22: 6 | H22: КМС | I22: 19 | J22: Куанышбеков Алмат+ | K22: =IF(LEFT(P38,1)="L",0,(IF(P38="","",(IF(LEFT(P38,1)>RIGHT(P38,1),2,1))))) -> 1 | L22: =IF(RIGHT(P33,1)="L",0,(IF(P33="","",(IF(RIGHT(P33,1)>LEFT(P33,1),2,1))))) -> 2 | M22: =IF(LEFT(P48,1)="L",0,(IF(P48="","",(IF(LEFT(P48,1)>RIGHT(P48,1),2,1))))) -> 2 | N22: =IF(RIGHT(P43,1)="L",0,(IF(P43="","",(IF(RIGHT(P43,1)>LEFT(P43,1),2,1))))) -> 2 | O22: =IF(RIGHT(P59,1)="L",0,(IF(P59="","",(IF(RIGHT(P59,1)>LEFT(P59,1),2,1))))) -> 2 | Q22: =IF(RIGHT(P55,1)="L",0,(IF(P55="","",(IF(RIGHT(P55,1)>LEFT(P55,1),2,1))))) -> 1 | R22: =IF(LEFT(P52,1)="L",0,(IF(P52="","",(IF(LEFT(P52,1)>RIGHT(P52,1),2,1))))) -> 2 | S22: =IF((AND(COUNTIF(J7:J30,">""")>2,COUNTIF(P33:P60,">""")>0)),SUM(K22,L22,M22,N22,O22,P22,Q22,R22),"") -> 12 | U22: 2
B23: 3:1 | K23: =IF(LEFT(P38,1)="W",$M$4&":0(W)",IF(LEFT(P38,1)="L","0:"&$M$4&"(L)",IF(P38="","",P38))) -> 2:3 | L23: =IF(RIGHT(P33,1)="W",$M$4&":0(W)",IF(RIGHT(P33,1)="L","0:"&$M$4&"(L)",IF(P33="","",RIGHT(P33,1)&":"&LEFT(P33,1)))) -> 3:2 | M23: =IF(LEFT(P48,1)="W",$M$4&":0(W)",IF(LEFT(P48,1)="L","0:"&$M$4&"(L)",IF(P48="","",P48))) -> 3:2 | N23: =IF(RIGHT(P43,1)="W",$M$4&":0(W)",IF(RIGHT(P43,1)="L","0:"&$M$4&"(L)",IF(P43="","",RIGHT(P43,1)&":"&LEFT(P43,1)))) -> 3:2 | O23: =IF(RIGHT(P59,1)="W",$M$4&":0(W)",IF(RIGHT(P59,1)="L","0:"&$M$4&"(L)",IF(P59="","",RIGHT(P59,1)&":"&LEFT(P59,1)))) -> 3:2 | Q23: =IF(RIGHT(P55,1)="W",$M$4&":0(W)",IF(RIGHT(P55,1)="L","0:"&$M$4&"(L)",IF(P55="","",RIGHT(P55,1)&":"&LEFT(P55,1)))) -> 0:3 | R23: =IF(LEFT(P52,1)="W",$M$4&":0(W)",IF(LEFT(P52,1)="L","0:"&$M$4&"(L)",IF(P52="","",P52))) -> 3:0
B24: 3:2 | K24: =IF(P38="","",IF(Q38="","",Q38)) | L24: =IF(P33="","",IF(Q33="","",REPLACE(SUBSTITUTE(SUBSTITUTE(SUBSTITUTE(SUBSTITUTE(","&Q33,",-","#"),",","-"),"#",","),"-",",-"),1,1,""))) | M24: =IF(P48="","",IF(Q48="","",Q48)) | N24: =IF(P43="","",IF(Q43="","",REPLACE(SUBSTITUTE(SUBSTITUTE(SUBSTITUTE(SUBSTITUTE(","&Q43,",-","#"),",","-"),"#",","),"-",",-"),1,1,""))) | O24: =IF(P59="","",IF(Q59="","",REPLACE(SUBSTITUTE(SUBSTITUTE(SUBSTITUTE(SUBSTITUTE(","&Q59,",-","#"),",","-"),"#",","),"-",",-"),1,1,""))) | Q24: =IF(P55="","",IF(Q55="","",REPLACE(SUBSTITUTE(SUBSTITUTE(SUBSTITUTE(SUBSTITUTE(","&Q55,",-","#"),",","-"),"#",","),"-",",-"),1,1,""))) | R24: =IF(P52="","",IF(Q52="","",Q52))
B25: 0:3 | G25: 7 | I25: 18 | J25: Боченин Игорь+ | K25: =IF(RIGHT(P35,1)="L",0,(IF(P35="","",(IF(RIGHT(P35,1)>LEFT(P35,1),2,1))))) -> 1 | L25: =IF(LEFT(P47,1)="L",0,(IF(P47="","",(IF(LEFT(P47,1)>RIGHT(P47,1),2,1))))) -> 1 | M25: =IF(RIGHT(P44,1)="L",0,(IF(P44="","",(IF(RIGHT(P44,1)>LEFT(P44,1),2,1))))) -> 1 | N25: =IF(LEFT(P40,1)="L",0,(IF(P40="","",(IF(LEFT(P40,1)>RIGHT(P40,1),2,1))))) -> 2 | O25: =IF(RIGHT(P51,1)="L",0,(IF(P51="","",(IF(RIGHT(P51,1)>LEFT(P51,1),2,1))))) -> 2 | P25: =IF(LEFT(P55,1)="L",0,(IF(P55="","",(IF(LEFT(P55,1)>RIGHT(P55,1),2,1))))) -> 2 | R25: =IF(LEFT(P60,1)="L",0,(IF(P60="","",(IF(LEFT(P60,1)>RIGHT(P60,1),2,1))))) -> 2 | S25: =IF((AND(COUNTIF(J7:J30,">""")>2,COUNTIF(P33:P60,">""")>0)),SUM(K25,L25,M25,N25,O25,P25,Q25,R25),"") -> 11 | U25: 5
B26: 1:3 | K26: =IF(RIGHT(P35,1)="W",$M$4&":0(W)",IF(RIGHT(P35,1)="L","0:"&$M$4&"(L)",IF(P35="","",RIGHT(P35,1)&":"&LEFT(P35,1)))) -> 2:3 | L26: =IF(LEFT(P47)="W",$M$4&":0(W)",IF(LEFT(P47,1)="L","0:"&$M$4&"(L)",IF(P47="","",P47))) -> 2:3 | M26: =IF(RIGHT(P44,1)="W",$M$4&":0(W)",IF(RIGHT(P44,1)="L","0:"&$M$4&"(L)",IF(P44="","",RIGHT(P44,1)&":"&LEFT(P44,1)))) -> 0:3 | N26: =IF(LEFT(P40,1)="W",$M$4&":0(W)",IF(LEFT(P40,1)="L","0:"&$M$4&"(L)",IF(P40="","",P40))) -> 3:1 | O26: =IF(RIGHT(P51,1)="W",$M$4&":0(W)",IF(RIGHT(P51,1)="L","0:"&$M$4&"(L)",IF(P51="","",RIGHT(P51,1)&":"&LEFT(P51,1)))) -> 3:0(W) | P26: =IF(LEFT(P55,1)="W",$M$4&":0(W)",IF(LEFT(P55,1)="L","0:"&$M$4&"(L)",IF(P55="","",P55))) -> 3:0 | R26: =IF(LEFT(P60,1)="W",$M$4&":0(W)",IF(LEFT(P60,1)="L","0:"&$M$4&"(L)",IF(P60="","",P60))) -> 3:0
B27: 2:3 | K27: =IF(P35="","",IF(Q35="","",REPLACE(SUBSTITUTE(SUBSTITUTE(SUBSTITUTE(SUBSTITUTE(","&Q35,",-","#"),",","-"),"#",","),"-",",-"),1,1,""))) | L27: =IF(P47="","",IF(Q47="","",Q47)) | M27: =IF(P44="","",IF(Q44="","",REPLACE(SUBSTITUTE(SUBSTITUTE(SUBSTITUTE(SUBSTITUTE(","&Q44,",-","#"),",","-"),"#",","),"-",",-"),1,1,""))) | N27: =IF(P40="","",IF(Q40="","",Q40)) | O27: =IF(P51="","",IF(Q51="","",REPLACE(SUBSTITUTE(SUBSTITUTE(SUBSTITUTE(SUBSTITUTE(","&Q51,",-","#"),",","-"),"#",","),"-",",-"),1,1,""))) | P27: =IF(P55="","",IF(Q55="","",Q55)) | R27: =IF(P60="","",IF(Q60="","",Q60))
